Workbook

Sheet Data sources
B1: Tags | G1: Emissions factors (tCO2e/t production) | M1: Status | N1: Process temperature | O1: Note | P1: Production | Q1: Source | R1: SEC (Fuel) | S1: SEC (Feedstock) | U1: Market growth EU SAM GEM3 22 | W1: Note
B2: Level 1 | C2: Level 2 | D2: Level 3 | E2: Level 4 | G2: Weighted | J2: Allocation | M2: Status | N2: Peak process temperature | O2: Note | P2: T | R2: GJ/T | S2: GJ/T | U2: %, 2023-2030 | V2: %, 2030-2050
G3: T/CO2e | H3: T | J3: T/CO2e | K3: T
A4: Non-ferrous metals
A5: [Primary] Aluminium | G5: 1.641 | J5: 1.464 | M5: Confirmed | N5: >500 (primary), 200-500 (processing) | P5: =IFERROR(K5/J5,0) -> 0 | Q5: Kiemel et al (2024) | R5: 12.024 | S5: 0 | U5: 0.83923856 | V5: 0.99183493 | W5: Non-ferrous metals
A6: Copper [n.a.] | G6: 1.4 | J6: 1.4 | M6: Confirmed | N6: >500 (primary), 200-500 (processing) | P6: =IFERROR(K6/J6,0) -> 0 | Q6: Kiemel et al (2024) | R6: 8.028 | S6: 0 | U6: 0.83923856 | V6: 0.99183493 | W6: Non-ferrous metals
A7: Lead, zinc and tin [n.a.] | G7: 1.92 | J7: 1.92 | M7: Confirmed | N7: >500 (primary), 200-500 (processing) | O7: Approx. Zinc and general metal processing | P7: =IFERROR(K7/J7,0) -> 0 | Q7: Kiemel et al (2024) | R7: 2.268 | S7: 0 | U7: 0.83923856 | V7: 0.99183493 | W7: Non-ferrous metals
A8: Non-ferrous metals [WA] | G8: =AVERAGE(G5:G7) -> 1.6536667 | J8: =AVERAGE(J5:J7) -> 1.5946667 | M8: Confirmed | N8: >500 (primary), 200-500 (processing) | O8: Approx. Zinc and general metal processing | P8: =IFERROR(K8/J8,0) -> 0 | Q8: Kiemel et al (2024) | R8: 2.268 | S8: 0 | U8: 0.83923856 | V8: 0.99183493 | W8: Non-ferrous metals
A9: Chemicals
A10: Ammonia | B10: Chemicals | C10: Inorganic | D10: Fertilizer | G10: 1.947 | H10: 30588525 | J10: 1.57 | K10: 23958607 | M10: Confirmed | N10: - | O10: Haber-Bosch process | P10: =IFERROR(K10/J10,0) -> 15260259 | Q10: Kiemel et al (2024) | R10: 0 | S10: 21.312 | U10: 0.84137119 | V10: 0.86357922 | W10: Chemical products
A11: Nitric acid | B11: Chemicals | C11: Inorganic | D11: Fertilizer | E11: Pharmaceuticals | G11: 0.205 | H11: 4614965 | J11: 0.23 | K11: 4614965 | M11: Confirmed | N11: - | O11: Ammonia oxidation (0.285t ammonia per to nitric acid) | P11: =IFERROR(K11/J11,0) -> 20065065 | Q11: Kiemel et al (2024) | R11: 0 | S11: 5.96736 | U11: 0.84137119 | V11: 0.86357922 | W11: Chemical products
A12: Soda ash | B12: Chemicals | C12: Inorganic | G12: 0.945 | H12: 7218816 | J12: 0.753 | K12: 5497992 | M12: Confirmed | N12: 100-200 | O12: Solvay process / H2-burner in furnace | P12: =IFERROR(K12/J12,0) -> 7301450.2 | Q12: Kiemel et al (2024) | R12: 11.304 | S12: 0 | U12: 0.84137119 | V12: 0.86357922 | W12: Chemical products
A13: Carbon Black | B13: Chemicals | C13: Inorganic | G13: 1.824 | H13: 1824820 | J13: 1.485 | K13: 1394408 | M13: Confirmed | N13: > 500 | O13: H2 burner in furnace | P13: =IFERROR(K13/J13,0) -> 938995.29 | Q13: Kiemel et al (2024) | R13: 64.8 | S13: 0 | U13: 0.84137119 | V13: 0.86357922 | W13: Chemical products
A14: Steam cracking | B14: Chemicals | C14: Organic | G14: 0.849 | H14: 31393609 | J14: 0.681 | K14: 22816634 | M14: Confirmed | N14: - | O14: Methanol-to-Olefins (Etyhlene) | P14: =IFERROR(K14/J14,0) -> 33504602 | Q14: Kiemel et al (2024) | R14: 0 | S14: 63.612 | U14: 0.84137119 | V14: 0.86357922 | W14: Chemical products
A15: Adipic Acid | B15: Chemicals | C15: Organic | D15: Plastics | E15: Pharmaceuticals | G15: 1.14 | H15: 857225 | J15: 2.12 | K15: 1468379 | M15: Confirmed | N15: <100 | O15: Primarily Steam, 20% efficiency upside | P15: =IFERROR(K15/J15,0) -> 692631.6 | Q15: IEA | R15: 21.6 | S15: 0 | U15: 0.84137119 | V15: 0.86357922 | W15: Chemical products
A16: Aromatics | B16: Chemicals | C16: Organic | G16: =0.0072*1/0.056 -> 0.12857143 | H16: 1896871 | J16: =0.0228*1/0.056 -> 0.40714286 | K16: 1139604 | M16: Confirmed | N16: > 500 | O16: Average of Benzene, Toluene, Xylone aromatics extraction, 20% efficiency upside | P16: =IFERROR(K16/J16,0) -> 2799027.4 | Q16: IEA | R16: 2.2 | S16: 37.333333 | U16: 0.84137119 | V16: 0.86357922 | W16: Chemical products
A17: Styrene | B17: Chemicals | C17: Organic | D17: Plastics | G17: 0.558 | H17: 2676322 | J17: 0.401 | K17: 1655811 | M17: Confirmed | N17: > 500 | O17: Steam, 20% efficiency upside | P17: =IFERROR(K17/J17,0) -> 4129204.5 | Q17: IEA | R17: 8.6 | S17: 0 | U17: 0.84137119 | V17: 0.86357922 | W17: Chemical products
A18: Phenol/Acetone | B18: Chemicals | C18: Organic | D18: Plastics | G18: 0.319 | H18: 1200943 | J18: 0.23 | K18: 812138 | M18: Confirmed | N18: 100-200 | O18: Steam, 20% efficiency upside | P18: =IFERROR(K18/J18,0) -> 3531034.8 | Q18: IEA | R18: 10.5 | S18: 0 | U18: 0.84137119 | V18: 0.86357922 | W18: Chemical products
A19: Ethylene oxide/ethylene glycol | B19: Chemicals | C19: Organic | D19: Plastics | E19: Pharmaceuticals | G19: 0.51 | H19: 1484310 | J19: 0.389 | K19: 839637 | M19: Confirmed | N19: 200-500 | O19: Steam, 20% efficiency upside | P19: =IFERROR(K19/J19,0) -> 2158449.9 | Q19: IEA | R19: 3.65 | S19: 0 | U19: 0.84137119 | V19: 0.86357922 | W19: Chemical products
A20: Vinyl chloride monomer | B20: Chemicals | C20: Organic | D20: Plastics | G20: 0.277 | H20: 1639059 | J20: 0.155 | K20: 758335 | M20: Confirmed | N20: > 500 | O20: Primarily Fuel, 20% efficiency upside | P20: =IFERROR(K20/J20,0) -> 4892483.9 | Q20: IEA | R20: 2.7 | S20: 0 | U20: 0.84137119 | V20: 0.86357922 | W20: Chemical products
A21: S-PVC | B21: Chemicals | C21: Organic | D21: Plastics | G21: 0.12 | H21: 400288 | J21: 0.066 | K21: 216193 | M21: Confirmed | N21: <100 | O21: Steam, 20% efficiency upside | P21: =IFERROR(K21/J21,0) -> 3275651.5 | Q21: IEA | R21: 1.9 | S21: 0 | U21: 0.84137119 | V21: 0.86357922 | W21: Chemical products
A22: E-PVC | B22: Chemicals | C22: Organic | D22: Plastics | G22: 0.23 | H22: 96197 | J22: 0.181 | K22: 61707 | M22: Confirmed | N22: <100 | O22: Steam, 20% efficiency upside | P22: =IFERROR(K22/J22,0) -> 340922.65 | Q22: IEA | R22: 1.9 | S22: 0 | U22: 0.84137119 | V22: 0.86357922 | W22: Chemical products
A23: Hydrogen and SynGas
A24: Hydrogen | B24: Hydrogen and Syngas | G24: 8.88 | H24: 7051720 | J24: 6.84 | K24: 5074480 | M24: Confirmed | N24: - | O24: Hydrogen LHV | P24: =IFERROR(K24/J24,0) -> 741883.04 | Q24: NREL | S24: 120.04802 | U24: 0.84137119 | V24: 0.86357922 | W24: Chemical products
A25: Snythetic Gas | B25: Hydrogen and Syngas | G25: 0.155 | H25: 357368 | J25: 0.187 | K25: 317371 | M25: Confirmed | N25: - | O25: Hydrogen LHV | P25: =IFERROR(K25/J25,0) -> 1697171.1 | Q25: NREL | S25: 120.04802 | U25: 0.84137119 | V25: 0.86357922 | W25: Chemical products
A26: Iron & Steel
A27: Sintered ore | G27: 0.248 | H27: 23154801 | J27: 0.157 | K27: 14393515 | M27: Confirmed | N27: > 500 | O27: Updraft sintering | P27: =IFERROR(K27/J27,0) -> 91678439 | Q27: Kiemel et al (2024) | R27: 2.232 | S27: 0 | U27: 0.55465093 | V27: 0.43306202 | W27: Ferrous metals
A28: Hot metal | B28: Integrated Steel | G28: 1.495 | H28: 128889587 | J28: 1.288 | K28: 110024564 | M28: Confirmed | N28: > 500 | O28: H2-DRI to hot metal | P28: =IFERROR(K28/J28,0) -> 85422798 | Q28: Kiemel et al (2024) | R28: 14.976 | S28: 6.804 | U28: 0.55465093 | V28: 0.43306202 | W28: Ferrous metals
A29: EAF carbon steel | B29: Steel Processing | G29: 0.255 | H29: 9804572 | J29: 0.215 | K29: 2050637 | M29: Confirmed | N29: > 500 | O29: Ferrous metal processing, assuming no mass losses between liquid steel and rolling | P29: =IFERROR(K29/J29,0) -> 9537846.5 | Q29: Kiemel et al (2024) | R29: 2.4768 | S29: 0 | U29: 0.55465093 | V29: 0.43306202 | W29: Ferrous metals
A30: EAF high alloy steel | B30: Steel Processing | G30: 0.323 | H30: 8681596 | J30: 0.268 | K30: 2185759 | M30: Confirmed | N30: > 500 | O30: Ferrous metal processing, assuming no mass losses between liquid steel and rolling | P30: =IFERROR(K30/J30,0) -> 8155817.2 | Q30: Kiemel et al (2024) | R30: 2.4768 | S30: 0 | U30: 0.55465093 | V30: 0.43306202 | W30: Ferrous metals
A31: Iron casting | G31: 0.37 | H31: 1380242 | J31: 0.282 | K31: 930583 | M31: Confirmed | N31: > 500 | O31: Ferrous metal processing, assuming no mass losses between liquid steel and rolling | P31: =IFERROR(K31/J31,0) -> 3299939.7 | Q31: Kiemel et al (2024) | R31: 2.4768 | S31: 0 | U31: 0.55465093 | V31: 0.43306202 | W31: Ferrous metals
A32: Refining
A33: Refinery products | G33: =0.0308/0.056 -> 0.55 | J33: =0.0228/0.056 -> 0.40714286 | M33: Confirmed | N33: - | O33: No distinction applied between hydrocracking and hydrotreating | P33: =IFERROR(K33/J33,0) -> 0 | Q33: Kiemel et al (2024) | R33: 0 | S33: 0.432 | U33: 0.75247639 | V33: 0.39034567 | W33: Crude oil
A34: Coke | G34: 0.282 | J34: 0.217 | M34: Confirmed | N34: - | O34: Excluded from consideration | P34: =IFERROR(K34/J34,0) -> 0 | Q34: Excluded | R34: 0 | S34: 0 | U34: 0.75247639 | V34: 0.39034567 | W34: Crude oil
A35: Non-metallic mineral products
A36: Grey cement clinker | B36: Non-metallic minerals | C36: Cement | G36: 0.81 | H36: 105321006 | J36: 0.693 | K36: 90105535 | M36: Confirmed | N36: >500 (Firing),100-300 (Drying) | O36: Approx. cement/clinker general | P36: =IFERROR(K36/J36,0) -> 1.3002242e+08 | Q36: Kiemel et al (2024) | R36: 4.32 | S36: 0 | U36: 0.66884535 | V36: 0.58742625 | W36: Non-metallic minerals
A37: White cement clinker | B37: Non-metallic minerals | C37: Cement | G37: 1.114 | H37: 2646157 | J37: 0.957 | K37: 2145323 | M37: Confirmed | N37: >500 (Firing),100-300 (Drying) | O37: Approx. cement/clinker general | P37: =IFERROR(K37/J37,0) -> 2241716.8 | Q37: Kiemel et al (2024) | R37: 4.32 | S37: 0 | U37: 0.66884535 | V37: 0.58742625 | W37: Non-metallic minerals
A38: Lime | B38: Non-metallic minerals | C38: Lime | G38: 1.059 | H38: 21751588 | J38: 0.725 | K38: 15062292 | M38: Confirmed | N38: > 500 | O38: Default to Neuwirth: Lime burning | P38: =IFERROR(K38/J38,0) -> 20775575 | Q38: Neuwirth et al (2022) | R38: 3.708 | S38: 0 | U38: 0.66884535 | V38: 0.58742625 | W38: Non-metallic minerals
A39: Dolime | B39: Non-metallic minerals | C39: Lime | G39: 1.214 | H39: 1794640 | J39: 0.815 | K39: 1265828 | M39: Confirmed | N39: > 500 | O39: Default to Neuwirth: Lime burning | P39: =IFERROR(K39/J39,0) -> 1553163.2 | Q39: Neuwirth et al (2022) | R39: 3.708 | S39: 0 | U39: 0.66884535 | V39: 0.58742625 | W39: Non-metallic minerals
A40: Sintered Dolime | B40: Non-metallic minerals | C40: Lime | G40: 1.535 | H40: 790184 | J40: 1.406 | K40: 722297 | M40: Confirmed | N40: > 500 | O40: Default to Neuwirth: Lime burning | P40: =IFERROR(K40/J40,0) -> 513724.75 | Q40: Neuwirth et al (2022) | R40: 3.708 | S40: 0 | U40: 0.66884535 | V40: 0.58742625 | W40: Non-metallic minerals
...

Sheet Allocation
A1: activity_type | B1: description | C1: nace_level2 | D1: Sector | E1: Industry | F1: Freq | G1: ETS BM Reference | H1: BM | I1: BM_AL | J1: fuel | K1: feedstock | L1: key | M1: Index_2030 | N1: Index_2050
A2: Combustion installations with a rated thermal input exceeding 20 MW | B2: Aluminium production | C2: Basic metals | D2: Non-ferrous metals | E2: Aluminium | F2: 4 | G2: [Primary] Aluminium | H2: =INDEX('Data sources'!G:G,MATCH(G2,'Data sources'!A:A,0),1) -> 1.641 | I2: =INDEX('Data sources'!J:J,MATCH(G2,'Data sources'!A:A,0),1) -> 1.464 | J2: =INDEX('Data sources'!R:R,MATCH(G2,'Data sources'!A:A,0),1) -> 12.024 | K2: =INDEX('Data sources'!S:S,MATCH(G2,'Data sources'!A:A,0),1) -> 0 | L2: =IF(B2="",A2,A2&"_"&B2) -> Combustion installations with a rated thermal input exceeding 20 MW_Aluminium production | M2: =INDEX('Data sources'!U:U,MATCH($G2,'Data sources'!$A:$A,0),1) -> 0.83923856 | N2: =INDEX('Data sources'!V:V,MATCH($G2,'Data sources'!$A:$A,0),1) -> 0.99183493
A3: Combustion installations with a rated thermal input exceeding 20 MW | B3: Manufacture of cement | C3: Non-metallic mineral products | D3: Non-metallic minerals | E3: Cement | F3: 1 | G3: Cement [WA] | H3: =INDEX('Data sources'!G:G,MATCH(G3,'Data sources'!A:A,0),1) -> 0.81745071 | I3: =INDEX('Data sources'!J:J,MATCH(G3,'Data sources'!A:A,0),1) -> 0.6991394 | J3: =INDEX('Data sources'!R:R,MATCH(G3,'Data sources'!A:A,0),1) -> 4.32 | K3: =INDEX('Data sources'!S:S,MATCH(G3,'Data sources'!A:A,0),1) -> 0 | L3: =IF(B3="",A3,A3&"_"&B3) -> Combustion installations with a rated thermal input exceeding 20 MW_Manufacture of cement | M3: =INDEX('Data sources'!U:U,MATCH($G3,'Data sources'!$A:$A,0),1) -> 0.66884535 | N3: =INDEX('Data sources'!V:V,MATCH($G3,'Data sources'!$A:$A,0),1) -> 0.58742625
A4: Combustion installations with a rated thermal input exceeding 20 MW | B4: Manufacture of concrete products for construction purposes | C4: Non-metallic mineral products | D4: Non-metallic minerals | E4: Cement | F4: 1 | G4: Cement [WA] | H4: =INDEX('Data sources'!G:G,MATCH(G4,'Data sources'!A:A,0),1) -> 0.81745071 | I4: =INDEX('Data sources'!J:J,MATCH(G4,'Data sources'!A:A,0),1) -> 0.6991394 | J4: =INDEX('Data sources'!R:R,MATCH(G4,'Data sources'!A:A,0),1) -> 4.32 | K4: =INDEX('Data sources'!S:S,MATCH(G4,'Data sources'!A:A,0),1) -> 0 | L4: =IF(B4="",A4,A4&"_"&B4) -> Combustion installations with a rated thermal input exceeding 20 MW_Manufacture of concrete products for construction purposes | M4: =INDEX('Data sources'!U:U,MATCH($G4,'Data sources'!$A:$A,0),1) -> 0.66884535 | N4: =INDEX('Data sources'!V:V,MATCH($G4,'Data sources'!$A:$A,0),1) -> 0.58742625
A5: Combustion installations with a rated thermal input exceeding 20 MW | B5: Manufacture of fibre cement | C5: Non-metallic mineral products | D5: Non-metallic minerals | E5: Cement | F5: 1 | G5: Cement [WA] | H5: =INDEX('Data sources'!G:G,MATCH(G5,'Data sources'!A:A,0),1) -> 0.81745071 | I5: =INDEX('Data sources'!J:J,MATCH(G5,'Data sources'!A:A,0),1) -> 0.6991394 | J5: =INDEX('Data sources'!R:R,MATCH(G5,'Data sources'!A:A,0),1) -> 4.32 | K5: =INDEX('Data sources'!S:S,MATCH(G5,'Data sources'!A:A,0),1) -> 0 | L5: =IF(B5="",A5,A5&"_"&B5) -> Combustion installations with a rated thermal input exceeding 20 MW_Manufacture of fibre cement | M5: =INDEX('Data sources'!U:U,MATCH($G5,'Data sources'!$A:$A,0),1) -> 0.66884535 | N5: =INDEX('Data sources'!V:V,MATCH($G5,'Data sources'!$A:$A,0),1) -> 0.58742625
A6: Combustion installations with a rated thermal input exceeding 20 MW | B6: Manufacture of bricks, tiles and construction products, in baked clay | C6: Non-metallic mineral products | D6: Non-metallic minerals | E6: Ceramics | F6: 3 | G6: Ceramics [WA] | H6: =INDEX('Data sources'!G:G,MATCH(G6,'Data sources'!A:A,0),1) -> 0.12876363 | I6: =INDEX('Data sources'!J:J,MATCH(G6,'Data sources'!A:A,0),1) -> 0.095090361 | J6: =INDEX('Data sources'!R:R,MATCH(G6,'Data sources'!A:A,0),1) -> 3.0746808 | K6: =INDEX('Data sources'!S:S,MATCH(G6,'Data sources'!A:A,0),1) -> 0 | L6: =IF(B6="",A6,A6&"_"&B6) -> Combustion installations with a rated thermal input exceeding 20 MW_Manufacture of bricks, tiles and construction products, in baked clay | M6: =INDEX('Data sources'!U:U,MATCH($G6,'Data sources'!$A:$A,0),1) -> 0.66884535 | N6: =INDEX('Data sources'!V:V,MATCH($G6,'Data sources'!$A:$A,0),1) -> 0.58742625
A7: Combustion installations with a rated thermal input exceeding 20 MW | B7: Manufacture of ceramic household and ornamental articles | C7: Non-metallic mineral products | D7: Non-metallic minerals | E7: Ceramics | F7: 4 | G7: Ceramics [WA] | H7: =INDEX('Data sources'!G:G,MATCH(G7,'Data sources'!A:A,0),1) -> 0.12876363 | I7: =INDEX('Data sources'!J:J,MATCH(G7,'Data sources'!A:A,0),1) -> 0.095090361 | J7: =INDEX('Data sources'!R:R,MATCH(G7,'Data sources'!A:A,0),1) -> 3.0746808 | K7: =INDEX('Data sources'!S:S,MATCH(G7,'Data sources'!A:A,0),1) -> 0 | L7: =IF(B7="",A7,A7&"_"&B7) -> Combustion installations with a rated thermal input exceeding 20 MW_Manufacture of ceramic household and ornamental articles | M7: =INDEX('Data sources'!U:U,MATCH($G7,'Data sources'!$A:$A,0),1) -> 0.66884535 | N7: =INDEX('Data sources'!V:V,MATCH($G7,'Data sources'!$A:$A,0),1) -> 0.58742625
A8: Combustion installations with a rated thermal input exceeding 20 MW | B8: Manufacture of ceramic sanitary fixtures | C8: Non-metallic mineral products | D8: Non-metallic minerals | E8: Ceramics | F8: 1 | G8: Ceramics [WA] | H8: =INDEX('Data sources'!G:G,MATCH(G8,'Data sources'!A:A,0),1) -> 0.12876363 | I8: =INDEX('Data sources'!J:J,MATCH(G8,'Data sources'!A:A,0),1) -> 0.095090361 | J8: =INDEX('Data sources'!R:R,MATCH(G8,'Data sources'!A:A,0),1) -> 3.0746808 | K8: =INDEX('Data sources'!S:S,MATCH(G8,'Data sources'!A:A,0),1) -> 0 | L8: =IF(B8="",A8,A8&"_"&B8) -> Combustion installations with a rated thermal input exceeding 20 MW_Manufacture of ceramic sanitary fixtures | M8: =INDEX('Data sources'!U:U,MATCH($G8,'Data sources'!$A:$A,0),1) -> 0.66884535 | N8: =INDEX('Data sources'!V:V,MATCH($G8,'Data sources'!$A:$A,0),1) -> 0.58742625
A9: Combustion installations with a rated thermal input exceeding 20 MW | B9: Manufacture of other porcelain and ceramic products | C9: Non-metallic mineral products | D9: Non-metallic minerals | E9: Ceramics | F9: 1 | G9: Ceramics [WA] | H9: =INDEX('Data sources'!G:G,MATCH(G9,'Data sources'!A:A,0),1) -> 0.12876363 | I9: =INDEX('Data sources'!J:J,MATCH(G9,'Data sources'!A:A,0),1) -> 0.095090361 | J9: =INDEX('Data sources'!R:R,MATCH(G9,'Data sources'!A:A,0),1) -> 3.0746808 | K9: =INDEX('Data sources'!S:S,MATCH(G9,'Data sources'!A:A,0),1) -> 0 | L9: =IF(B9="",A9,A9&"_"&B9) -> Combustion installations with a rated thermal input exceeding 20 MW_Manufacture of other porcelain and ceramic products | M9: =INDEX('Data sources'!U:U,MATCH($G9,'Data sources'!$A:$A,0),1) -> 0.66884535 | N9: =INDEX('Data sources'!V:V,MATCH($G9,'Data sources'!$A:$A,0),1) -> 0.58742625
A10: Combustion installations with a rated thermal input exceeding 20 MW | B10: Production of abrasive products | C10: Non-metallic mineral products | D10: Non-metallic minerals | E10: Ceramics | F10: 1 | G10: Ceramics [WA] | H10: =INDEX('Data sources'!G:G,MATCH(G10,'Data sources'!A:A,0),1) -> 0.12876363 | I10: =INDEX('Data sources'!J:J,MATCH(G10,'Data sources'!A:A,0),1) -> 0.095090361 | J10: =INDEX('Data sources'!R:R,MATCH(G10,'Data sources'!A:A,0),1) -> 3.0746808 | K10: =INDEX('Data sources'!S:S,MATCH(G10,'Data sources'!A:A,0),1) -> 0 | L10: =IF(B10="",A10,A10&"_"&B10) -> Combustion installations with a rated thermal input exceeding 20 MW_Production of abrasive products | M10: =INDEX('Data sources'!U:U,MATCH($G10,'Data sources'!$A:$A,0),1) -> 0.66884535 | N10: =INDEX('Data sources'!V:V,MATCH($G10,'Data sources'!$A:$A,0),1) -> 0.58742625
A11: Combustion installations with a rated thermal input exceeding 20 MW | B11: Manufacture of basic pharmaceutical products | C11: Pharmaceuticals | D11: Chemicals | E11: Pharmaceuticals | F11: 1 | G11: Chemicals [Acids and Ethylenoxid/Ethylenglykol subset, WA] | H11: =INDEX('Data sources'!G:G,MATCH(G11,'Data sources'!A:A,0),1) -> 0.38529468 | I11: =INDEX('Data sources'!J:J,MATCH(G11,'Data sources'!A:A,0),1) -> 0.65015695 | J11: =INDEX('Data sources'!R:R,MATCH(G11,'Data sources'!A:A,0),1) -> 0.99664158 | K11: =INDEX('Data sources'!S:S,MATCH(G11,'Data sources'!A:A,0),1) -> 5.224939 | L11: =IF(B11="",A11,A11&"_"&B11) -> Combustion installations with a rated thermal input exceeding 20 MW_Manufacture of basic pharmaceutical products | M11: =INDEX('Data sources'!U:U,MATCH($G11,'Data sources'!$A:$A,0),1) -> 0.84137119 | N11: =INDEX('Data sources'!V:V,MATCH($G11,'Data sources'!$A:$A,0),1) -> 0.86357922
A12: Combustion installations with a rated thermal input exceeding 20 MW | B12: Manufacture of dyes and pigments | C12: Chemicals | D12: Chemicals | E12: Chemicals | F12: 1 | G12: Chemicals [WA] | H12: =INDEX('Data sources'!G:G,MATCH(G12,'Data sources'!A:A,0),1) -> 1.1838611 | I12: =INDEX('Data sources'!J:J,MATCH(G12,'Data sources'!A:A,0),1) -> 1.0013516 | J12: =INDEX('Data sources'!R:R,MATCH(G12,'Data sources'!A:A,0),1) -> 2.6802341 | K12: =INDEX('Data sources'!S:S,MATCH(G12,'Data sources'!A:A,0),1) -> 27.108503 | L12: =IF(B12="",A12,A12&"_"&B12) -> Combustion installations with a rated thermal input exceeding 20 MW_Manufacture of dyes and pigments | M12: =INDEX('Data sources'!U:U,MATCH($G12,'Data sources'!$A:$A,0),1) -> 0.84137119 | N12: =INDEX('Data sources'!V:V,MATCH($G12,'Data sources'!$A:$A,0),1) -> 0.86357922
A13: Combustion installations with a rated thermal input exceeding 20 MW | B13: Manufacture of industrial gases | C13: Chemicals | D13: Chemicals | E13: Chemicals | F13: 3 | G13: Hydrogen and synthetic gas [WA] | H13: =INDEX('Data sources'!G:G,MATCH(G13,'Data sources'!A:A,0),1) -> 8.4591606 | I13: =INDEX('Data sources'!J:J,MATCH(G13,'Data sources'!A:A,0),1) -> 6.4483962 | J13: =INDEX('Data sources'!R:R,MATCH(G13,'Data sources'!A:A,0),1) -> 0 | K13: =INDEX('Data sources'!S:S,MATCH(G13,'Data sources'!A:A,0),1) -> 120.04802 | L13: =IF(B13="",A13,A13&"_"&B13) -> Combustion installations with a rated thermal input exceeding 20 MW_Manufacture of industrial gases | M13: =INDEX('Data sources'!U:U,MATCH($G13,'Data sources'!$A:$A,0),1) -> 0.84137119 | N13: =INDEX('Data sources'!V:V,MATCH($G13,'Data sources'!$A:$A,0),1) -> 0.86357922
... A106: Combustion installations with a rated thermal input exceeding 20 MW | B106: Manufacture of plastic plates, sheets, tubes and profiles | C106: Rubber & plastic | D106: Chemicals | E106: Chemicals | F106: 4 | G106: Chemicals [WA, Plastics subset] | H106: =INDEX('Data sources'!G:G,MATCH(G106,'Data sources'!A:A,0),1) -> 0.49494039 | I106: =INDEX('Data sources'!J:J,MATCH(G106,'Data sources'!A:A,0),1) -> 0.76276347 | J106: =INDEX('Data sources'!R:R,MATCH(G106,'Data sources'!A:A,0),1) -> 6.0728236 | K106: =INDEX('Data sources'!S:S,MATCH(G106,'Data sources'!A:A,0),1) -> 0 | L106: =IF(B106="",A106,A106&"_"&B106) -> Combustion installations with a rated thermal input exceeding 20 MW_Manufacture of plastic plates, sheets, tubes and profiles | M106: =INDEX('Data sources'!U:U,MATCH($G106,'Data sources'!$A:$A,0),1) -> 0.84137119 | N106: =INDEX('Data sources'!V:V,MATCH($G106,'Data sources'!$A:$A,0),1) -> 0.86357922
A107: Combustion installations with a rated thermal input exceeding 20 MW | D107: Other | E107: Other combustion | G107: Fuel Benchmark | H107: =INDEX('Data sources'!G:G,MATCH(G107,'Data sources'!A:A,0),1) -> 0.0579 | I107: =INDEX('Data sources'!J:J,MATCH(G107,'Data sources'!A:A,0),1) -> 0.0426 | J107: =INDEX('Data sources'!R:R,MATCH(G107,'Data sources'!A:A,0),1) -> 1 | K107: =INDEX('Data sources'!S:S,MATCH(G107,'Data sources'!A:A,0),1) -> 0 | L107: =IF(B107="",A107,A107&"_"&B107) -> Combustion installations with a rated thermal input exceeding 20 MW | M107: =INDEX('Data sources'!U:U,MATCH($G107,'Data sources'!$A:$A,0),1) -> 0.78416348 | N107: =INDEX('Data sources'!V:V,MATCH($G107,'Data sources'!$A:$A,0),1) -> 0.7253514
A108: Combustion of fuels | B108: Aluminium production | C108: Basic metals | D108: Non-ferrous metals | E108: Aluminium | F108: 8 | G108: [Primary] Aluminium | H108: =INDEX('Data sources'!G:G,MATCH(G108,'Data sources'!A:A,0),1) -> 1.641 | I108: =INDEX('Data sources'!J:J,MATCH(G108,'Data sources'!A:A,0),1) -> 1.464 | J108: =INDEX('Data sources'!R:R,MATCH(G108,'Data sources'!A:A,0),1) -> 12.024 | K108: =INDEX('Data sources'!S:S,MATCH(G108,'Data sources'!A:A,0),1) -> 0 | L108: =IF(B108="",A108,A108&"_"&B108) -> Combustion of fuels_Aluminium production | M108: =INDEX('Data sources'!U:U,MATCH($G108,'Data sources'!$A:$A,0),1) -> 0.83923856 | N108: =INDEX('Data sources'!V:V,MATCH($G108,'Data sources'!$A:$A,0),1) -> 0.99183493
A109: Combustion of fuels | B109: Manufacture of cement | C109: Non-metallic mineral products | D109: Non-metallic minerals | E109: Cement | F109: 1 | G109: Cement [WA] | H109: =INDEX('Data sources'!G:G,MATCH(G109,'Data sources'!A:A,0),1) -> 0.81745071 | I109: =INDEX('Data sources'!J:J,MATCH(G109,'Data sources'!A:A,0),1) -> 0.6991394 | J109: =INDEX('Data sources'!R:R,MATCH(G109,'Data sources'!A:A,0),1) -> 4.32 | K109: =INDEX('Data sources'!S:S,MATCH(G109,'Data sources'!A:A,0),1) -> 0 | L109: =IF(B109="",A109,A109&"_"&B109) -> Combustion of fuels_Manufacture of cement | M109: =INDEX('Data sources'!U:U,MATCH($G109,'Data sources'!$A:$A,0),1) -> 0.66884535 | N109: =INDEX('Data sources'!V:V,MATCH($G109,'Data sources'!$A:$A,0),1) -> 0.58742625
A110: Combustion of fuels | B110: Manufacture of concrete products for construction purposes | C110: Non-metallic mineral products | D110: Non-metallic minerals | E110: Cement | F110: 2 | G110: Cement [WA] | H110: =INDEX('Data sources'!G:G,MATCH(G110,'Data sources'!A:A,0),1) -> 0.81745071 | I110: =INDEX('Data sources'!J:J,MATCH(G110,'Data sources'!A:A,0),1) -> 0.6991394 | J110: =INDEX('Data sources'!R:R,MATCH(G110,'Data sources'!A:A,0),1) -> 4.32 | K110: =INDEX('Data sources'!S:S,MATCH(G110,'Data sources'!A:A,0),1) -> 0 | L110: =IF(B110="",A110,A110&"_"&B110) -> Combustion of fuels_Manufacture of concrete products for construction purposes | M110: =INDEX('Data sources'!U:U,MATCH($G110,'Data sources'!$A:$A,0),1) -> 0.66884535 | N110: =INDEX('Data sources'!V:V,MATCH($G110,'Data sources'!$A:$A,0),1) -> 0.58742625
A111: Combustion of fuels | B111: Manufacture of fibre cement | C111: Non-metallic mineral products | D111: Non-metallic minerals | E111: Cement | F111: 2 | G111: Cement [WA] | H111: =INDEX('Data sources'!G:G,MATCH(G111,'Data sources'!A:A,0),1) -> 0.81745071 | I111: =INDEX('Data sources'!J:J,MATCH(G111,'Data sources'!A:A,0),1) -> 0.6991394 | J111: =INDEX('Data sources'!R:R,MATCH(G111,'Data sources'!A:A,0),1) -> 4.32 | K111: =INDEX('Data sources'!S:S,MATCH(G111,'Data sources'!A:A,0),1) -> 0 | L111: =IF(B111="",A111,A111&"_"&B111) -> Combustion of fuels_Manufacture of fibre cement | M111: =INDEX('Data sources'!U:U,MATCH($G111,'Data sources'!$A:$A,0),1) -> 0.66884535 | N111: =INDEX('Data sources'!V:V,MATCH($G111,'Data sources'!$A:$A,0),1) -> 0.58742625
A112: Combustion of fuels | B112: Manufacture of bricks, tiles and construction products, in baked clay | C112: Non-metallic mineral products | D112: Non-metallic minerals | E112: Ceramics | F112: 2 | G112: Ceramics [WA] | H112: =INDEX('Data sources'!G:G,MATCH(G112,'Data sources'!A:A,0),1) -> 0.12876363 | I112: =INDEX('Data sources'!J:J,MATCH(G112,'Data sources'!A:A,0),1) -> 0.095090361 | J112: =INDEX('Data sources'!R:R,MATCH(G112,'Data sources'!A:A,0),1) -> 3.0746808 | K112: =INDEX('Data sources'!S:S,MATCH(G112,'Data sources'!A:A,0),1) -> 0 | L112: =IF(B112="",A112,A112&"_"&B112) -> Combustion of fuels_Manufacture of bricks, tiles and construction products, in baked clay | M112: =INDEX('Data sources'!U:U,MATCH($G112,'Data sources'!$A:$A,0),1) -> 0.66884535 | N112: =INDEX('Data sources'!V:V,MATCH($G112,'Data sources'!$A:$A,0),1) -> 0.58742625
A113: Combustion of fuels | B113: Manufacture of ceramic insulators and insulating fittings | C113: Non-metallic mineral products | D113: Non-metallic minerals | E113: Ceramics | F113: 1 | G113: Ceramics [WA] | H113: =INDEX('Data sources'!G:G,MATCH(G113,'Data sources'!A:A,0),1) -> 0.12876363 | I113: =INDEX('Data sources'!J:J,MATCH(G113,'Data sources'!A:A,0),1) -> 0.095090361 | J113: =INDEX('Data sources'!R:R,MATCH(G113,'Data sources'!A:A,0),1) -> 3.0746808 | K113: =INDEX('Data sources'!S:S,MATCH(G113,'Data sources'!A:A,0),1) -> 0 | L113: =IF(B113="",A113,A113&"_"&B113) -> Combustion of fuels_Manufacture of ceramic insulators and insulating fittings | M113: =INDEX('Data sources'!U:U,MATCH($G113,'Data sources'!$A:$A,0),1) -> 0.66884535 | N113: =INDEX('Data sources'!V:V,MATCH($G113,'Data sources'!$A:$A,0),1) -> 0.58742625
A114: Combustion of fuels | B114: Manufacture of ceramic sanitary fixtures | C114: Non-metallic mineral products | D114: Non-metallic minerals | E114: Ceramics | F114: 1 | G114: Ceramics [WA] | H114: =INDEX('Data sources'!G:G,MATCH(G114,'Data sources'!A:A,0),1) -> 0.12876363 | I114: =INDEX('Data sources'!J:J,MATCH(G114,'Data sources'!A:A,0),1) -> 0.095090361 | J114: =INDEX('Data sources'!R:R,MATCH(G114,'Data sources'!A:A,0),1) -> 3.0746808 | K114: =INDEX('Data sources'!S:S,MATCH(G114,'Data sources'!A:A,0),1) -> 0 | L114: =IF(B114="",A114,A114&"_"&B114) -> Combustion of fuels_Manufacture of ceramic sanitary fixtures | M114: =INDEX('Data sources'!U:U,MATCH($G114,'Data sources'!$A:$A,0),1) -> 0.66884535 | N114: =INDEX('Data sources'!V:V,MATCH($G114,'Data sources'!$A:$A,0),1) -> 0.58742625
A115: Combustion of fuels | B115: Manufacture of ceramic tiles and flags | C115: Non-metallic mineral products | D115: Non-metallic minerals | E115: Ceramics | F115: 2 | G115: Ceramics [WA] | H115: =INDEX('Data sources'!G:G,MATCH(G115,'Data sources'!A:A,0),1) -> 0.12876363 | I115: =INDEX('Data sources'!J:J,MATCH(G115,'Data sources'!A:A,0),1) -> 0.095090361 | J115: =INDEX('Data sources'!R:R,MATCH(G115,'Data sources'!A:A,0),1) -> 3.0746808 | K115: =INDEX('Data sources'!S:S,MATCH(G115,'Data sources'!A:A,0),1) -> 0 | L115: =IF(B115="",A115,A115&"_"&B115) -> Combustion of fuels_Manufacture of ceramic tiles and flags | M115: =INDEX('Data sources'!U:U,MATCH($G115,'Data sources'!$A:$A,0),1) -> 0.66884535 | N115: =INDEX('Data sources'!V:V,MATCH($G115,'Data sources'!$A:$A,0),1) -> 0.58742625
A116: Combustion of fuels | B116: Manufacture of basic pharmaceutical products | C116: Pharmaceuticals | D116: Chemicals | E116: Pharmaceuticals | F116: 23 | G116: Chemicals [WA] | H116: =INDEX('Data sources'!G:G,MATCH(G116,'Data sources'!A:A,0),1) -> 1.1838611 | I116: =INDEX('Data sources'!J:J,MATCH(G116,'Data sources'!A:A,0),1) -> 1.0013516 | J116: =INDEX('Data sources'!R:R,MATCH(G116,'Data sources'!A:A,0),1) -> 2.6802341 | K116: =INDEX('Data sources'!S:S,MATCH(G116,'Data sources'!A:A,0),1) -> 27.108503 | L116: =IF(B116="",A116,A116&"_"&B116) -> Combustion of fuels_Manufacture of basic pharmaceutical products | M116: =INDEX('Data sources'!U:U,MATCH($G116,'Data sources'!$A:$A,0),1) -> 0.84137119 | N116: =INDEX('Data sources'!V:V,MATCH($G116,'Data sources'!$A:$A,0),1) -> 0.86357922
A117: Combustion of fuels | B117: Manufacture of dyes and pigments | C117: Chemicals | D117: Chemicals | E117: Chemicals | F117: 10 | G117: Chemicals [WA] | H117: =INDEX('Data sources'!G:G,MATCH(G117,'Data sources'!A:A,0),1) -> 1.1838611 | I117: =INDEX('Data sources'!J:J,MATCH(G117,'Data sources'!A:A,0),1) -> 1.0013516 | J117: =INDEX('Data sources'!R:R,MATCH(G117,'Data sources'!A:A,0),1) -> 2.6802341 | K117: =INDEX('Data sources'!S:S,MATCH(G117,'Data sources'!A:A,0),1) -> 27.108503 | L117: =IF(B117="",A117,A117&"_"&B117) -> Combustion of fuels_Manufacture of dyes and pigments | M117: =INDEX('Data sources'!U:U,MATCH($G117,'Data sources'!$A:$A,0),1) -> 0.84137119 | N117: =INDEX('Data sources'!V:V,MATCH($G117,'Data sources'!$A:$A,0),1) -> 0.86357922
A118: Combustion of fuels | B118: Manufacture of explosives | C118: Chemicals | D118: Chemicals | E118: Chemicals | F118: 1 | G118: Chemicals [WA] | H118: =INDEX('Data sources'!G:G,MATCH(G118,'Data sources'!A:A,0),1) -> 1.1838611 | I118: =INDEX('Data sources'!J:J,MATCH(G118,'Data sources'!A:A,0),1) -> 1.0013516 | J118: =INDEX('Data sources'!R:R,MATCH(G118,'Data sources'!A:A,0),1) -> 2.6802341 | K118: =INDEX('Data sources'!S:S,MATCH(G118,'Data sources'!A:A,0),1) -> 27.108503 | L118: =IF(B118="",A118,A118&"_"&B118) -> Combustion of fuels_Manufacture of explosives | M118: =INDEX('Data sources'!U:U,MATCH($G118,'Data sources'!$A:$A,0),1) -> 0.84137119 | N118: =INDEX('Data sources'!V:V,MATCH($G118,'Data sources'!$A:$A,0),1) -> 0.86357922
A119: Combustion of fuels | B119: Manufacture of fertilisers and nitrogen compounds | C119: Chemicals | D119: Chemicals | E119: Chemicals | F119: 29 | G119: Chemicals [Ammonia and Nitric Acid subset, WA] | H119: =INDEX('Data sources'!G:G,MATCH(G119,'Data sources'!A:A,0),1) -> 1.7186343 | I119: =INDEX('Data sources'!J:J,MATCH(G119,'Data sources'!A:A,0),1) -> 1.3535744 | J119: =INDEX('Data sources'!R:R,MATCH(G119,'Data sources'!A:A,0),1) -> 0 | K119: =INDEX('Data sources'!S:S,MATCH(G119,'Data sources'!A:A,0),1) -> 12.596122 | L119: =IF(B119="",A119,A119&"_"&B119) -> Combustion of fuels_Manufacture of fertilisers and nitrogen compounds | M119: =INDEX('Data sources'!U:U,MATCH($G119,'Data sources'!$A:$A,0),1) -> 0.84137119 | N119: =INDEX('Data sources'!V:V,MATCH($G119,'Data sources'!$A:$A,0),1) -> 0.86357922
... A277: Combustion of fuels | B277: Manufacture of rubber tyres and tubes | C277: Rubber & plastic | D277: Chemicals | E277: Chemicals | F277: 23 | G277: Chemicals [WA, Plastics subset] | H277: =INDEX('Data sources'!G:G,MATCH(G277,'Data sources'!A:A,0),1) -> 0.49494039 | I277: =INDEX('Data sources'!J:J,MATCH(G277,'Data sources'!A:A,0),1) -> 0.76276347 | J277: =INDEX('Data sources'!R:R,MATCH(G277,'Data sources'!A:A,0),1) -> 6.0728236 | K277: =INDEX('Data sources'!S:S,MATCH(G277,'Data sources'!A:A,0),1) -> 0 | L277: =IF(B277="",A277,A277&"_"&B277) -> Combustion of fuels_Manufacture of rubber tyres and tubes | M277: =INDEX('Data sources'!U:U,MATCH($G277,'Data sources'!$A:$A,0),1) -> 0.84137119 | N277: =INDEX('Data sources'!V:V,MATCH($G277,'Data sources'!$A:$A,0),1) -> 0.86357922
A278: Combustion of fuels | D278: Other | E278: Other combustion | G278: Fuel Benchmark | H278: =INDEX('Data sources'!G:G,MATCH(G278,'Data sources'!A:A,0),1) -> 0.0579 | I278: =INDEX('Data sources'!J:J,MATCH(G278,'Data sources'!A:A,0),1) -> 0.0426 | J278: =INDEX('Data sources'!R:R,MATCH(G278,'Data sources'!A:A,0),1) -> 1 | K278: =INDEX('Data sources'!S:S,MATCH(G278,'Data sources'!A:A,0),1) -> 0 | L278: =IF(B278="",A278,A278&"_"&B278) -> Combustion of fuels | M278: =INDEX('Data sources'!U:U,MATCH($G278,'Data sources'!$A:$A,0),1) -> 0.78416348 | N278: =INDEX('Data sources'!V:V,MATCH($G278,'Data sources'!$A:$A,0),1) -> 0.7253514
A279: Industrial plants for the production of (a) pulp from timber or other fibrous materials (b) paper and board | B279: Manufacture of paper and paperboard | C279: Pulp & Paper | D279: Pulp & paper | E279: Paper | F279: 70 | G279: Paper [WA] | H279: =INDEX('Data sources'!G:G,MATCH(G279,'Data sources'!A:A,0),1) -> 0.22011858 | I279: =INDEX('Data sources'!J:J,MATCH(G279,'Data sources'!A:A,0),1) -> 0.22144474 | J279: =INDEX('Data sources'!R:R,MATCH(G279,'Data sources'!A:A,0),1) -> 6.1071929 | K279: =INDEX('Data sources'!S:S,MATCH(G279,'Data sources'!A:A,0),1) -> 0 | L279: =IF(B279="",A279,A279&"_"&B279) -> Industrial plants for the production of (a) pulp from timber or other fibrous materials (b) paper and board_Manufacture of paper and paperboard | M279: =INDEX('Data sources'!U:U,MATCH($G279,'Data sources'!$A:$A,0),1) -> 0.81657744 | N279: =INDEX('Data sources'!V:V,MATCH($G279,'Data sources'!$A:$A,0),1) -> 0.94441453
A280: Industrial plants for the production of (a) pulp from timber or other fibrous materials (b) paper and board | B280: Electric power generation, transmission and distribution | C280: Electricity, gas, steam and air conditioning supply | D280: Power and heat | E280: Power and heat | F280: 1 | G280: Fuel Benchmark | H280: =INDEX('Data sources'!G:G,MATCH(G280,'Data sources'!A:A,0),1) -> 0.0579 | I280: =INDEX('Data sources'!J:J,MATCH(G280,'Data sources'!A:A,0),1) -> 0.0426 | J280: =INDEX('Data sources'!R:R,MATCH(G280,'Data sources'!A:A,0),1) -> 1 | K280: =INDEX('Data sources'!S:S,MATCH(G280,'Data sources'!A:A,0),1) -> 0 | L280: =IF(B280="",A280,A280&"_"&B280) -> Industrial plants for the production of (a) pulp from timber or other fibrous materials (b) paper and board_Electric power generation, transmission and distribution | M280: =INDEX('Data sources'!U:U,MATCH($G280,'Data sources'!$A:$A,0),1) -> 0.78416348 | N280: =INDEX('Data sources'!V:V,MATCH($G280,'Data sources'!$A:$A,0),1) -> 0.7253514
A281: Industrial plants for the production of (a) pulp from timber or other fibrous materials (b) paper and board | B281: Electricity, gas, steam and air conditioning supply | C281: Electricity, gas, steam and air conditioning supply | D281: Power and heat | E281: Power and heat | F281: 1 | G281: Heat Benchmark | H281: =INDEX('Data sources'!G:G,MATCH(G281,'Data sources'!A:A,0),1) -> 0.0768 | I281: =INDEX('Data sources'!J:J,MATCH(G281,'Data sources'!A:A,0),1) -> 0.0473 | J281: =INDEX('Data sources'!R:R,MATCH(G281,'Data sources'!A:A,0),1) -> 1 | K281: =INDEX('Data sources'!S:S,MATCH(G281,'Data sources'!A:A,0),1) -> 0 | L281: =IF(B281="",A281,A281&"_"&B281) -> Industrial plants for the production of (a) pulp from timber or other fibrous materials (b) paper and board_Electricity, gas, steam and air conditioning supply | M281: =INDEX('Data sources'!U:U,MATCH($G281,'Data sources'!$A:$A,0),1) -> 0.78416348 | N281: =INDEX('Data sources'!V:V,MATCH($G281,'Data sources'!$A:$A,0),1) -> 0.7253514
A282: Industrial plants for the production of (a) pulp from timber or other fibrous materials (b) paper and board | B282: Manufacture of pulp | C282: Pulp & Paper | D282: Pulp & paper | E282: Pulp | F282: 9 | G282: Pulp [WA] | H282: =INDEX('Data sources'!G:G,MATCH(G282,'Data sources'!A:A,0),1) -> 0.070004406 | I282: =INDEX('Data sources'!J:J,MATCH(G282,'Data sources'!A:A,0),1) -> 0.046589293 | J282: =INDEX('Data sources'!R:R,MATCH(G282,'Data sources'!A:A,0),1) -> 3.2582614 | K282: =INDEX('Data sources'!S:S,MATCH(G282,'Data sources'!A:A,0),1) -> 0 | L282: =IF(B282="",A282,A282&"_"&B282) -> Industrial plants for the production of (a) pulp from timber or other fibrous materials (b) paper and board_Manufacture of pulp | M282: =INDEX('Data sources'!U:U,MATCH($G282,'Data sources'!$A:$A,0),1) -> 0.81657744 | N282: =INDEX('Data sources'!V:V,MATCH($G282,'Data sources'!$A:$A,0),1) -> 0.94441453
A283: Industrial plants for the production of (a) pulp from timber or other fibrous materials (b) paper and board | B283: Manufacture of household and sanitary goods and of toilet requisites | C283: Pulp & Paper | D283: Pulp & paper | E283: Paper | F283: 1 | G283: Paper [WA] | H283: =INDEX('Data sources'!G:G,MATCH(G283,'Data sources'!A:A,0),1) -> 0.22011858 | I283: =INDEX('Data sources'!J:J,MATCH(G283,'Data sources'!A:A,0),1) -> 0.22144474 | J283: =INDEX('Data sources'!R:R,MATCH(G283,'Data sources'!A:A,0),1) -> 6.1071929 | K283: =INDEX('Data sources'!S:S,MATCH(G283,'Data sources'!A:A,0),1) -> 0 | L283: =IF(B283="",A283,A283&"_"&B283) -> Industrial plants for the production of (a) pulp from timber or other fibrous materials (b) paper and board_Manufacture of household and sanitary goods and of toilet requisites | M283: =INDEX('Data sources'!U:U,MATCH($G283,'Data sources'!$A:$A,0),1) -> 0.81657744 | N283: =INDEX('Data sources'!V:V,MATCH($G283,'Data sources'!$A:$A,0),1) -> 0.94441453
A284: Industrial plants for the production of (a) pulp from timber or other fibrous materials (b) paper and board | D284: Pulp & paper | E284: 0 | G284: Pulp & Paper [WA] | H284: =INDEX('Data sources'!G:G,MATCH(G284,'Data sources'!A:A,0),1) -> 0.19771476 | I284: =INDEX('Data sources'!J:J,MATCH(G284,'Data sources'!A:A,0),1) -> 0.20319124 | J284: =INDEX('Data sources'!R:R,MATCH(G284,'Data sources'!A:A,0),1) -> 4.9612622 | K284: =INDEX('Data sources'!S:S,MATCH(G284,'Data sources'!A:A,0),1) -> 0 | L284: =IF(B284="",A284,A284&"_"&B284) -> Industrial plants for the production of (a) pulp from timber or other fibrous materials (b) paper and board | M284: =INDEX('Data sources'!U:U,MATCH($G284,'Data sources'!$A:$A,0),1) -> 0.81657744 | N284: =INDEX('Data sources'!V:V,MATCH($G284,'Data sources'!$A:$A,0),1) -> 0.94441453
A285: Installations for the manufacture of ceramic products by firing, in particular roofing tiles, bricks, refractory bricks, tiles, stoneware or porcelain | B285: Manufacture of concrete products for construction purposes | C285: Non-metallic mineral products | D285: Non-metallic minerals | E285: Cement | F285: 1 | G285: Cement [WA] | H285: =INDEX('Data sources'!G:G,MATCH(G285,'Data sources'!A:A,0),1) -> 0.81745071 | I285: =INDEX('Data sources'!J:J,MATCH(G285,'Data sources'!A:A,0),1) -> 0.6991394 | J285: =INDEX('Data sources'!R:R,MATCH(G285,'Data sources'!A:A,0),1) -> 4.32 | K285: =INDEX('Data sources'!S:S,MATCH(G285,'Data sources'!A:A,0),1) -> 0 | L285: =IF(B285="",A285,A285&"_"&B285) -> Installations for the manufacture of ceramic products by firing, in particular roofing tiles, bricks, refractory bricks, tiles, stoneware or porcelain_Manufacture of concrete products for construction purposes | M285: =INDEX('Data sources'!U:U,MATCH($G285,'Data sources'!$A:$A,0),1) -> 0.66884535 | N285: =INDEX('Data sources'!V:V,MATCH($G285,'Data sources'!$A:$A,0),1) -> 0.58742625
A286: Installations for the manufacture of ceramic products by firing, in particular roofing tiles, bricks, refractory bricks, tiles, stoneware or porcelain | B286: Manufacture of bricks, tiles and construction products, in baked clay | C286: Non-metallic mineral products | D286: Non-metallic minerals | E286: Ceramics | F286: 59 | G286: Ceramics [WA] | H286: =INDEX('Data sources'!G:G,MATCH(G286,'Data sources'!A:A,0),1) -> 0.12876363 | I286: =INDEX('Data sources'!J:J,MATCH(G286,'Data sources'!A:A,0),1) -> 0.095090361 | J286: =INDEX('Data sources'!R:R,MATCH(G286,'Data sources'!A:A,0),1) -> 3.0746808 | K286: =INDEX('Data sources'!S:S,MATCH(G286,'Data sources'!A:A,0),1) -> 0 | L286: =IF(B286="",A286,A286&"_"&B286) -> Installations for the manufacture of ceramic products by firing, in particular roofing tiles, bricks, refractory bricks, tiles, stoneware or porcelain_Manufacture of bricks, tiles and construction products, in baked clay | M286: =INDEX('Data sources'!U:U,MATCH($G286,'Data sources'!$A:$A,0),1) -> 0.66884535 | N286: =INDEX('Data sources'!V:V,MATCH($G286,'Data sources'!$A:$A,0),1) -> 0.58742625
A287: Installations for the manufacture of ceramic products by firing, in particular roofing tiles, bricks, refractory bricks, tiles, stoneware or porcelain | B287: Manufacture of ceramic household and ornamental articles | C287: Non-metallic mineral products | D287: Non-metallic minerals | E287: Ceramics | F287: 89 | G287: Ceramics [WA] | H287: =INDEX('Data sources'!G:G,MATCH(G287,'Data sources'!A:A,0),1) -> 0.12876363 | I287: =INDEX('Data sources'!J:J,MATCH(G287,'Data sources'!A:A,0),1) -> 0.095090361 | J287: =INDEX('Data sources'!R:R,MATCH(G287,'Data sources'!A:A,0),1) -> 3.0746808 | K287: =INDEX('Data sources'!S:S,MATCH(G287,'Data sources'!A:A,0),1) -> 0 | L287: =IF(B287="",A287,A287&"_"&B287) -> Installations for the manufacture of ceramic products by firing, in particular roofing tiles, bricks, refractory bricks, tiles, stoneware or porcelain_Manufacture of ceramic household and ornamental articles | M287: =INDEX('Data sources'!U:U,MATCH($G287,'Data sources'!$A:$A,0),1) -> 0.66884535 | N287: =INDEX('Data sources'!V:V,MATCH($G287,'Data sources'!$A:$A,0),1) -> 0.58742625
A288: Installations for the manufacture of ceramic products by firing, in particular roofing tiles, bricks, refractory bricks, tiles, stoneware or porcelain | B288: Manufacture of ceramic sanitary fixtures | C288: Non-metallic mineral products | D288: Non-metallic minerals | E288: Ceramics | F288: 3 | G288: Ceramics [WA] | H288: =INDEX('Data sources'!G:G,MATCH(G288,'Data sources'!A:A,0),1) -> 0.12876363 | I288: =INDEX('Data sources'!J:J,MATCH(G288,'Data sources'!A:A,0),1) -> 0.095090361 | J288: =INDEX('Data sources'!R:R,MATCH(G288,'Data sources'!A:A,0),1) -> 3.0746808 | K288: =INDEX('Data sources'!S:S,MATCH(G288,'Data sources'!A:A,0),1) -> 0 | L288: =IF(B288="",A288,A288&"_"&B288) -> Installations for the manufacture of ceramic products by firing, in particular roofing tiles, bricks, refractory bricks, tiles, stoneware or porcelain_Manufacture of ceramic sanitary fixtures | M288: =INDEX('Data sources'!U:U,MATCH($G288,'Data sources'!$A:$A,0),1) -> 0.66884535 | N288: =INDEX('Data sources'!V:V,MATCH($G288,'Data sources'!$A:$A,0),1) -> 0.58742625
A289: Installations for the manufacture of ceramic products by firing, in particular roofing tiles, bricks, refractory bricks, tiles, stoneware or porcelain | B289: Manufacture of ceramic tiles and flags | C289: Non-metallic mineral products | D289: Non-metallic minerals | E289: Ceramics | F289: 24 | G289: Ceramics [WA] | H289: =INDEX('Data sources'!G:G,MATCH(G289,'Data sources'!A:A,0),1) -> 0.12876363 | I289: =INDEX('Data sources'!J:J,MATCH(G289,'Data sources'!A:A,0),1) -> 0.095090361 | J289: =INDEX('Data sources'!R:R,MATCH(G289,'Data sources'!A:A,0),1) -> 3.0746808 | K289: =INDEX('Data sources'!S:S,MATCH(G289,'Data sources'!A:A,0),1) -> 0 | L289: =IF(B289="",A289,A289&"_"&B289) -> Installations for the manufacture of ceramic products by firing, in particular roofing tiles, bricks, refractory bricks, tiles, stoneware or porcelain_Manufacture of ceramic tiles and flags | M289: =INDEX('Data sources'!U:U,MATCH($G289,'Data sources'!$A:$A,0),1) -> 0.66884535 | N289: =INDEX('Data sources'!V:V,MATCH($G289,'Data sources'!$A:$A,0),1) -> 0.58742625
...
