Workbook

Sheet R Interface
A1: activity_type | B1: description | C1: nace_level2 | D1: Sector | E1: Industry | F1: Freq | G1: ETS BM Reference | H1: BM | I1: BM_AL | J1: fuel | K1: feedstock | L1: key | M1: Index_2030 | N1: Index_2050 | O1: Index_2030_Depr | P1: Index_2050_Depr | Q1: carbon_leakage
A2: Combustion installations with a rated thermal input exceeding 20 MW | B2: Aluminium production | C2: Basic metals | D2: Non-ferrous metals | E2: Aluminium | F2: 4 | G2: [Primary] Aluminium | H2: =INDEX(Data!G:G,MATCH(G2,Data!A:A,0),1) -> 1.641 | I2: =INDEX(Data!J:J,MATCH(G2,Data!A:A,0),1) -> 1.464 | J2: =INDEX(Data!R:R,MATCH(G2,Data!A:A,0),1) -> 12.024 | K2: =INDEX(Data!S:S,MATCH(G2,Data!A:A,0),1) -> 0 | L2: =IF(B2="",A2,A2&"_"&B2) -> Combustion installations with a rated thermal input exceeding 20 MW_Aluminium production | M2: =INDEX(Data!AD:AD,MATCH($G2,Data!$A:$A,0),1) -> 0.804 | N2: =INDEX(Data!AE:AE,MATCH($G2,Data!$A:$A,0),1) -> 0.858 | O2: =INDEX(Data!AG:AG,MATCH($G2,Data!$A:$A,0),1) -> 1.3517721 | P2: =INDEX(Data!AH:AH,MATCH($G2,Data!$A:$A,0),1) -> 3.1982578 | Q2: =IFERROR(IF(MATCH(B2,#REF!,0)>0,1),0) -> 0
A3: Combustion installations with a rated thermal input exceeding 20 MW | B3: Manufacture of cement | C3: Non-metallic mineral products | D3: Non-metallic minerals | E3: Cement | F3: 1 | G3: Cement [WA] | H3: =INDEX(Data!G:G,MATCH(G3,Data!A:A,0),1) -> 0.81745071 | I3: =INDEX(Data!J:J,MATCH(G3,Data!A:A,0),1) -> 0.6991394 | J3: =INDEX(Data!R:R,MATCH(G3,Data!A:A,0),1) -> 4.32 | K3: =INDEX(Data!S:S,MATCH(G3,Data!A:A,0),1) -> 0 | L3: =IF(B3="",A3,A3&"_"&B3) -> Combustion installations with a rated thermal input exceeding 20 MW_Manufacture of cement | M3: =INDEX(Data!AD:AD,MATCH($G3,Data!$A:$A,0),1) -> 0.6 | N3: =INDEX(Data!AE:AE,MATCH($G3,Data!$A:$A,0),1) -> 0.598 | O3: =INDEX(Data!AG:AG,MATCH($G3,Data!$A:$A,0),1) -> 1.7474276 | P3: =INDEX(Data!AH:AH,MATCH($G3,Data!$A:$A,0),1) -> 11.543913 | Q3: =IFERROR(IF(MATCH(B3,#REF!,0)>0,1),0) -> 0
A4: Combustion installations with a rated thermal input exceeding 20 MW | B4: Manufacture of concrete products for construction purposes | C4: Non-metallic mineral products | D4: Non-metallic minerals | E4: Cement | F4: 1 | G4: Cement [WA] | H4: =INDEX(Data!G:G,MATCH(G4,Data!A:A,0),1) -> 0.81745071 | I4: =INDEX(Data!J:J,MATCH(G4,Data!A:A,0),1) -> 0.6991394 | J4: =INDEX(Data!R:R,MATCH(G4,Data!A:A,0),1) -> 4.32 | K4: =INDEX(Data!S:S,MATCH(G4,Data!A:A,0),1) -> 0 | L4: =IF(B4="",A4,A4&"_"&B4) -> Combustion installations with a rated thermal input exceeding 20 MW_Manufacture of concrete products for construction purposes | M4: =INDEX(Data!AD:AD,MATCH($G4,Data!$A:$A,0),1) -> 0.6 | N4: =INDEX(Data!AE:AE,MATCH($G4,Data!$A:$A,0),1) -> 0.598 | O4: =INDEX(Data!AG:AG,MATCH($G4,Data!$A:$A,0),1) -> 1.7474276 | P4: =INDEX(Data!AH:AH,MATCH($G4,Data!$A:$A,0),1) -> 11.543913 | Q4: =IFERROR(IF(MATCH(B4,#REF!,0)>0,1),0) -> 0
A5: Combustion installations with a rated thermal input exceeding 20 MW | B5: Manufacture of fibre cement | C5: Non-metallic mineral products | D5: Non-metallic minerals | E5: Cement | F5: 1 | G5: Cement [WA] | H5: =INDEX(Data!G:G,MATCH(G5,Data!A:A,0),1) -> 0.81745071 | I5: =INDEX(Data!J:J,MATCH(G5,Data!A:A,0),1) -> 0.6991394 | J5: =INDEX(Data!R:R,MATCH(G5,Data!A:A,0),1) -> 4.32 | K5: =INDEX(Data!S:S,MATCH(G5,Data!A:A,0),1) -> 0 | L5: =IF(B5="",A5,A5&"_"&B5) -> Combustion installations with a rated thermal input exceeding 20 MW_Manufacture of fibre cement | M5: =INDEX(Data!AD:AD,MATCH($G5,Data!$A:$A,0),1) -> 0.6 | N5: =INDEX(Data!AE:AE,MATCH($G5,Data!$A:$A,0),1) -> 0.598 | O5: =INDEX(Data!AG:AG,MATCH($G5,Data!$A:$A,0),1) -> 1.7474276 | P5: =INDEX(Data!AH:AH,MATCH($G5,Data!$A:$A,0),1) -> 11.543913 | Q5: =IFERROR(IF(MATCH(B5,#REF!,0)>0,1),0) -> 0
A6: Combustion installations with a rated thermal input exceeding 20 MW | B6: Manufacture of bricks, tiles and construction products, in baked clay | C6: Non-metallic mineral products | D6: Non-metallic minerals | E6: Ceramics | F6: 3 | G6: Ceramics [WA] | H6: =INDEX(Data!G:G,MATCH(G6,Data!A:A,0),1) -> 0.12876363 | I6: =INDEX(Data!J:J,MATCH(G6,Data!A:A,0),1) -> 0.095090361 | J6: =INDEX(Data!R:R,MATCH(G6,Data!A:A,0),1) -> 3.0746808 | K6: =INDEX(Data!S:S,MATCH(G6,Data!A:A,0),1) -> 0 | L6: =IF(B6="",A6,A6&"_"&B6) -> Combustion installations with a rated thermal input exceeding 20 MW_Manufacture of bricks, tiles and construction products, in baked clay | M6: =INDEX(Data!AD:AD,MATCH($G6,Data!$A:$A,0),1) -> 0.6 | N6: =INDEX(Data!AE:AE,MATCH($G6,Data!$A:$A,0),1) -> 0.598 | O6: =INDEX(Data!AG:AG,MATCH($G6,Data!$A:$A,0),1) -> 1.1022134 | P6: =INDEX(Data!AH:AH,MATCH($G6,Data!$A:$A,0),1) -> 1.4555421 | Q6: =IFERROR(IF(MATCH(B6,#REF!,0)>0,1),0) -> 0
A7: Combustion installations with a rated thermal input exceeding 20 MW | B7: Manufacture of ceramic household and ornamental articles | C7: Non-metallic mineral products | D7: Non-metallic minerals | E7: Ceramics | F7: 4 | G7: Ceramics [WA] | H7: =INDEX(Data!G:G,MATCH(G7,Data!A:A,0),1) -> 0.12876363 | I7: =INDEX(Data!J:J,MATCH(G7,Data!A:A,0),1) -> 0.095090361 | J7: =INDEX(Data!R:R,MATCH(G7,Data!A:A,0),1) -> 3.0746808 | K7: =INDEX(Data!S:S,MATCH(G7,Data!A:A,0),1) -> 0 | L7: =IF(B7="",A7,A7&"_"&B7) -> Combustion installations with a rated thermal input exceeding 20 MW_Manufacture of ceramic household and ornamental articles | M7: =INDEX(Data!AD:AD,MATCH($G7,Data!$A:$A,0),1) -> 0.6 | N7: =INDEX(Data!AE:AE,MATCH($G7,Data!$A:$A,0),1) -> 0.598 | O7: =INDEX(Data!AG:AG,MATCH($G7,Data!$A:$A,0),1) -> 1.1022134 | P7: =INDEX(Data!AH:AH,MATCH($G7,Data!$A:$A,0),1) -> 1.4555421 | Q7: =IFERROR(IF(MATCH(B7,#REF!,0)>0,1),0) -> 0
A8: Combustion installations with a rated thermal input exceeding 20 MW | B8: Manufacture of ceramic sanitary fixtures | C8: Non-metallic mineral products | D8: Non-metallic minerals | E8: Ceramics | F8: 1 | G8: Ceramics [WA] | H8: =INDEX(Data!G:G,MATCH(G8,Data!A:A,0),1) -> 0.12876363 | I8: =INDEX(Data!J:J,MATCH(G8,Data!A:A,0),1) -> 0.095090361 | J8: =INDEX(Data!R:R,MATCH(G8,Data!A:A,0),1) -> 3.0746808 | K8: =INDEX(Data!S:S,MATCH(G8,Data!A:A,0),1) -> 0 | L8: =IF(B8="",A8,A8&"_"&B8) -> Combustion installations with a rated thermal input exceeding 20 MW_Manufacture of ceramic sanitary fixtures | M8: =INDEX(Data!AD:AD,MATCH($G8,Data!$A:$A,0),1) -> 0.6 | N8: =INDEX(Data!AE:AE,MATCH($G8,Data!$A:$A,0),1) -> 0.598 | O8: =INDEX(Data!AG:AG,MATCH($G8,Data!$A:$A,0),1) -> 1.1022134 | P8: =INDEX(Data!AH:AH,MATCH($G8,Data!$A:$A,0),1) -> 1.4555421 | Q8: =IFERROR(IF(MATCH(B8,#REF!,0)>0,1),0) -> 0
A9: Combustion installations with a rated thermal input exceeding 20 MW | B9: Manufacture of other porcelain and ceramic products | C9: Non-metallic mineral products | D9: Non-metallic minerals | E9: Ceramics | F9: 1 | G9: Ceramics [WA] | H9: =INDEX(Data!G:G,MATCH(G9,Data!A:A,0),1) -> 0.12876363 | I9: =INDEX(Data!J:J,MATCH(G9,Data!A:A,0),1) -> 0.095090361 | J9: =INDEX(Data!R:R,MATCH(G9,Data!A:A,0),1) -> 3.0746808 | K9: =INDEX(Data!S:S,MATCH(G9,Data!A:A,0),1) -> 0 | L9: =IF(B9="",A9,A9&"_"&B9) -> Combustion installations with a rated thermal input exceeding 20 MW_Manufacture of other porcelain and ceramic products | M9: =INDEX(Data!AD:AD,MATCH($G9,Data!$A:$A,0),1) -> 0.6 | N9: =INDEX(Data!AE:AE,MATCH($G9,Data!$A:$A,0),1) -> 0.598 | O9: =INDEX(Data!AG:AG,MATCH($G9,Data!$A:$A,0),1) -> 1.1022134 | P9: =INDEX(Data!AH:AH,MATCH($G9,Data!$A:$A,0),1) -> 1.4555421 | Q9: =IFERROR(IF(MATCH(B9,#REF!,0)>0,1),0) -> 0
A10: Combustion installations with a rated thermal input exceeding 20 MW | B10: Production of abrasive products | C10: Non-metallic mineral products | D10: Non-metallic minerals | E10: Ceramics | F10: 1 | G10: Ceramics [WA] | H10: =INDEX(Data!G:G,MATCH(G10,Data!A:A,0),1) -> 0.12876363 | I10: =INDEX(Data!J:J,MATCH(G10,Data!A:A,0),1) -> 0.095090361 | J10: =INDEX(Data!R:R,MATCH(G10,Data!A:A,0),1) -> 3.0746808 | K10: =INDEX(Data!S:S,MATCH(G10,Data!A:A,0),1) -> 0 | L10: =IF(B10="",A10,A10&"_"&B10) -> Combustion installations with a rated thermal input exceeding 20 MW_Production of abrasive products | M10: =INDEX(Data!AD:AD,MATCH($G10,Data!$A:$A,0),1) -> 0.6 | N10: =INDEX(Data!AE:AE,MATCH($G10,Data!$A:$A,0),1) -> 0.598 | O10: =INDEX(Data!AG:AG,MATCH($G10,Data!$A:$A,0),1) -> 1.1022134 | P10: =INDEX(Data!AH:AH,MATCH($G10,Data!$A:$A,0),1) -> 1.4555421 | Q10: =IFERROR(IF(MATCH(B10,#REF!,0)>0,1),0) -> 0
A11: Combustion installations with a rated thermal input exceeding 20 MW | B11: Manufacture of basic pharmaceutical products | C11: Pharmaceuticals | D11: Chemicals | E11: Pharmaceuticals | F11: 1 | G11: Chemicals [Acids and Ethylenoxid/Ethylenglykol subset, WA] | H11: =INDEX(Data!G:G,MATCH(G11,Data!A:A,0),1) -> 0.38529468 | I11: =INDEX(Data!J:J,MATCH(G11,Data!A:A,0),1) -> 0.65015695 | J11: =INDEX(Data!R:R,MATCH(G11,Data!A:A,0),1) -> 0.99664158 | K11: =INDEX(Data!S:S,MATCH(G11,Data!A:A,0),1) -> 5.224939 | L11: =IF(B11="",A11,A11&"_"&B11) -> Combustion installations with a rated thermal input exceeding 20 MW_Manufacture of basic pharmaceutical products | M11: =INDEX(Data!AD:AD,MATCH($G11,Data!$A:$A,0),1) -> 0.812 | N11: =INDEX(Data!AE:AE,MATCH($G11,Data!$A:$A,0),1) -> 0.739 | O11: =INDEX(Data!AG:AG,MATCH($G11,Data!$A:$A,0),1) -> 1.2983192 | P11: =INDEX(Data!AH:AH,MATCH($G11,Data!$A:$A,0),1) -> 4.8395672 | Q11: =IFERROR(IF(MATCH(B11,#REF!,0)>0,1),0) -> 0
A12: Combustion installations with a rated thermal input exceeding 20 MW | B12: Manufacture of dyes and pigments | C12: Chemicals | D12: Chemicals | E12: Chemicals | F12: 1 | G12: Chemicals [WA] | H12: =INDEX(Data!G:G,MATCH(G12,Data!A:A,0),1) -> 1.1838611 | I12: =INDEX(Data!J:J,MATCH(G12,Data!A:A,0),1) -> 1.0013516 | J12: =INDEX(Data!R:R,MATCH(G12,Data!A:A,0),1) -> 2.6802341 | K12: =INDEX(Data!S:S,MATCH(G12,Data!A:A,0),1) -> 27.108503 | L12: =IF(B12="",A12,A12&"_"&B12) -> Combustion installations with a rated thermal input exceeding 20 MW_Manufacture of dyes and pigments | M12: =INDEX(Data!AD:AD,MATCH($G12,Data!$A:$A,0),1) -> 0.812 | N12: =INDEX(Data!AE:AE,MATCH($G12,Data!$A:$A,0),1) -> 0.739 | O12: =INDEX(Data!AG:AG,MATCH($G12,Data!$A:$A,0),1) -> 1.326565 | P12: =INDEX(Data!AH:AH,MATCH($G12,Data!$A:$A,0),1) -> 6.8406135 | Q12: =IFERROR(IF(MATCH(B12,#REF!,0)>0,1),0) -> 0
A13: Combustion installations with a rated thermal input exceeding 20 MW | B13: Manufacture of industrial gases | C13: Chemicals | D13: Chemicals | E13: Chemicals | F13: 3 | G13: Hydrogen and synthetic gas [WA] | H13: =INDEX(Data!G:G,MATCH(G13,Data!A:A,0),1) -> 8.4591606 | I13: =INDEX(Data!J:J,MATCH(G13,Data!A:A,0),1) -> 6.4483962 | J13: =INDEX(Data!R:R,MATCH(G13,Data!A:A,0),1) -> 0 | K13: =INDEX(Data!S:S,MATCH(G13,Data!A:A,0),1) -> 120.04802 | L13: =IF(B13="",A13,A13&"_"&B13) -> Combustion installations with a rated thermal input exceeding 20 MW_Manufacture of industrial gases | M13: =INDEX(Data!AD:AD,MATCH($G13,Data!$A:$A,0),1) -> 0.812 | N13: =INDEX(Data!AE:AE,MATCH($G13,Data!$A:$A,0),1) -> 0.739 | O13: =INDEX(Data!AG:AG,MATCH($G13,Data!$A:$A,0),1) -> 1.2983192 | P13: =INDEX(Data!AH:AH,MATCH($G13,Data!$A:$A,0),1) -> 4.8395672 | Q13: =IFERROR(IF(MATCH(B13,#REF!,0)>0,1),0) -> 0
... A106: Combustion installations with a rated thermal input exceeding 20 MW | B106: Manufacture of plastic plates, sheets, tubes and profiles | C106: Rubber & plastic | D106: Chemicals | E106: Chemicals | F106: 4 | G106: Chemicals [WA, Plastics subset] | H106: =INDEX(Data!G:G,MATCH(G106,Data!A:A,0),1) -> 0.49494039 | I106: =INDEX(Data!J:J,MATCH(G106,Data!A:A,0),1) -> 0.76276347 | J106: =INDEX(Data!R:R,MATCH(G106,Data!A:A,0),1) -> 6.0728236 | K106: =INDEX(Data!S:S,MATCH(G106,Data!A:A,0),1) -> 0 | L106: =IF(B106="",A106,A106&"_"&B106) -> Combustion installations with a rated thermal input exceeding 20 MW_Manufacture of plastic plates, sheets, tubes and profiles | M106: =INDEX(Data!AD:AD,MATCH($G106,Data!$A:$A,0),1) -> 0.812 | N106: =INDEX(Data!AE:AE,MATCH($G106,Data!$A:$A,0),1) -> 0.739 | O106: =INDEX(Data!AG:AG,MATCH($G106,Data!$A:$A,0),1) -> 1.2983192 | P106: =INDEX(Data!AH:AH,MATCH($G106,Data!$A:$A,0),1) -> 4.8395672 | Q106: =IFERROR(IF(MATCH(B106,#REF!,0)>0,1),0) -> 0
A107: Combustion installations with a rated thermal input exceeding 20 MW | D107: Other | E107: Other combustion | G107: Fuel Benchmark | H107: =INDEX(Data!G:G,MATCH(G107,Data!A:A,0),1) -> 0.0579 | I107: =INDEX(Data!J:J,MATCH(G107,Data!A:A,0),1) -> 0.0426 | J107: =INDEX(Data!R:R,MATCH(G107,Data!A:A,0),1) -> 1 | K107: =INDEX(Data!S:S,MATCH(G107,Data!A:A,0),1) -> 0 | L107: =IF(B107="",A107,A107&"_"&B107) -> Combustion installations with a rated thermal input exceeding 20 MW | M107: =INDEX(Data!AD:AD,MATCH($G107,Data!$A:$A,0),1) -> 0.782 | N107: =INDEX(Data!AE:AE,MATCH($G107,Data!$A:$A,0),1) -> 0.635 | O107: =INDEX(Data!AG:AG,MATCH($G107,Data!$A:$A,0),1) -> 1.1486857 | P107: =INDEX(Data!AH:AH,MATCH($G107,Data!$A:$A,0),1) -> 1.7068865 | Q107: =IFERROR(IF(MATCH(B107,#REF!,0)>0,1),0) -> 0
A108: Combustion of fuels | B108: Aluminium production | C108: Basic metals | D108: Non-ferrous metals | E108: Aluminium | F108: 8 | G108: [Primary] Aluminium | H108: =INDEX(Data!G:G,MATCH(G108,Data!A:A,0),1) -> 1.641 | I108: =INDEX(Data!J:J,MATCH(G108,Data!A:A,0),1) -> 1.464 | J108: =INDEX(Data!R:R,MATCH(G108,Data!A:A,0),1) -> 12.024 | K108: =INDEX(Data!S:S,MATCH(G108,Data!A:A,0),1) -> 0 | L108: =IF(B108="",A108,A108&"_"&B108) -> Combustion of fuels_Aluminium production | M108: =INDEX(Data!AD:AD,MATCH($G108,Data!$A:$A,0),1) -> 0.804 | N108: =INDEX(Data!AE:AE,MATCH($G108,Data!$A:$A,0),1) -> 0.858 | O108: =INDEX(Data!AG:AG,MATCH($G108,Data!$A:$A,0),1) -> 1.3517721 | P108: =INDEX(Data!AH:AH,MATCH($G108,Data!$A:$A,0),1) -> 3.1982578 | Q108: =IFERROR(IF(MATCH(B108,#REF!,0)>0,1),0) -> 0
A109: Combustion of fuels | B109: Manufacture of cement | C109: Non-metallic mineral products | D109: Non-metallic minerals | E109: Cement | F109: 1 | G109: Cement [WA] | H109: =INDEX(Data!G:G,MATCH(G109,Data!A:A,0),1) -> 0.81745071 | I109: =INDEX(Data!J:J,MATCH(G109,Data!A:A,0),1) -> 0.6991394 | J109: =INDEX(Data!R:R,MATCH(G109,Data!A:A,0),1) -> 4.32 | K109: =INDEX(Data!S:S,MATCH(G109,Data!A:A,0),1) -> 0 | L109: =IF(B109="",A109,A109&"_"&B109) -> Combustion of fuels_Manufacture of cement | M109: =INDEX(Data!AD:AD,MATCH($G109,Data!$A:$A,0),1) -> 0.6 | N109: =INDEX(Data!AE:AE,MATCH($G109,Data!$A:$A,0),1) -> 0.598 | O109: =INDEX(Data!AG:AG,MATCH($G109,Data!$A:$A,0),1) -> 1.7474276 | P109: =INDEX(Data!AH:AH,MATCH($G109,Data!$A:$A,0),1) -> 11.543913 | Q109: =IFERROR(IF(MATCH(B109,#REF!,0)>0,1),0) -> 0
A110: Combustion of fuels | B110: Manufacture of concrete products for construction purposes | C110: Non-metallic mineral products | D110: Non-metallic minerals | E110: Cement | F110: 2 | G110: Cement [WA] | H110: =INDEX(Data!G:G,MATCH(G110,Data!A:A,0),1) -> 0.81745071 | I110: =INDEX(Data!J:J,MATCH(G110,Data!A:A,0),1) -> 0.6991394 | J110: =INDEX(Data!R:R,MATCH(G110,Data!A:A,0),1) -> 4.32 | K110: =INDEX(Data!S:S,MATCH(G110,Data!A:A,0),1) -> 0 | L110: =IF(B110="",A110,A110&"_"&B110) -> Combustion of fuels_Manufacture of concrete products for construction purposes | M110: =INDEX(Data!AD:AD,MATCH($G110,Data!$A:$A,0),1) -> 0.6 | N110: =INDEX(Data!AE:AE,MATCH($G110,Data!$A:$A,0),1) -> 0.598 | O110: =INDEX(Data!AG:AG,MATCH($G110,Data!$A:$A,0),1) -> 1.7474276 | P110: =INDEX(Data!AH:AH,MATCH($G110,Data!$A:$A,0),1) -> 11.543913 | Q110: =IFERROR(IF(MATCH(B110,#REF!,0)>0,1),0) -> 0
A111: Combustion of fuels | B111: Manufacture of fibre cement | C111: Non-metallic mineral products | D111: Non-metallic minerals | E111: Cement | F111: 2 | G111: Cement [WA] | H111: =INDEX(Data!G:G,MATCH(G111,Data!A:A,0),1) -> 0.81745071 | I111: =INDEX(Data!J:J,MATCH(G111,Data!A:A,0),1) -> 0.6991394 | J111: =INDEX(Data!R:R,MATCH(G111,Data!A:A,0),1) -> 4.32 | K111: =INDEX(Data!S:S,MATCH(G111,Data!A:A,0),1) -> 0 | L111: =IF(B111="",A111,A111&"_"&B111) -> Combustion of fuels_Manufacture of fibre cement | M111: =INDEX(Data!AD:AD,MATCH($G111,Data!$A:$A,0),1) -> 0.6 | N111: =INDEX(Data!AE:AE,MATCH($G111,Data!$A:$A,0),1) -> 0.598 | O111: =INDEX(Data!AG:AG,MATCH($G111,Data!$A:$A,0),1) -> 1.7474276 | P111: =INDEX(Data!AH:AH,MATCH($G111,Data!$A:$A,0),1) -> 11.543913 | Q111: =IFERROR(IF(MATCH(B111,#REF!,0)>0,1),0) -> 0
A112: Combustion of fuels | B112: Manufacture of bricks, tiles and construction products, in baked clay | C112: Non-metallic mineral products | D112: Non-metallic minerals | E112: Ceramics | F112: 2 | G112: Ceramics [WA] | H112: =INDEX(Data!G:G,MATCH(G112,Data!A:A,0),1) -> 0.12876363 | I112: =INDEX(Data!J:J,MATCH(G112,Data!A:A,0),1) -> 0.095090361 | J112: =INDEX(Data!R:R,MATCH(G112,Data!A:A,0),1) -> 3.0746808 | K112: =INDEX(Data!S:S,MATCH(G112,Data!A:A,0),1) -> 0 | L112: =IF(B112="",A112,A112&"_"&B112) -> Combustion of fuels_Manufacture of bricks, tiles and construction products, in baked clay | M112: =INDEX(Data!AD:AD,MATCH($G112,Data!$A:$A,0),1) -> 0.6 | N112: =INDEX(Data!AE:AE,MATCH($G112,Data!$A:$A,0),1) -> 0.598 | O112: =INDEX(Data!AG:AG,MATCH($G112,Data!$A:$A,0),1) -> 1.1022134 | P112: =INDEX(Data!AH:AH,MATCH($G112,Data!$A:$A,0),1) -> 1.4555421 | Q112: =IFERROR(IF(MATCH(B112,#REF!,0)>0,1),0) -> 0
A113: Combustion of fuels | B113: Manufacture of ceramic insulators and insulating fittings | C113: Non-metallic mineral products | D113: Non-metallic minerals | E113: Ceramics | F113: 1 | G113: Ceramics [WA] | H113: =INDEX(Data!G:G,MATCH(G113,Data!A:A,0),1) -> 0.12876363 | I113: =INDEX(Data!J:J,MATCH(G113,Data!A:A,0),1) -> 0.095090361 | J113: =INDEX(Data!R:R,MATCH(G113,Data!A:A,0),1) -> 3.0746808 | K113: =INDEX(Data!S:S,MATCH(G113,Data!A:A,0),1) -> 0 | L113: =IF(B113="",A113,A113&"_"&B113) -> Combustion of fuels_Manufacture of ceramic insulators and insulating fittings | M113: =INDEX(Data!AD:AD,MATCH($G113,Data!$A:$A,0),1) -> 0.6 | N113: =INDEX(Data!AE:AE,MATCH($G113,Data!$A:$A,0),1) -> 0.598 | O113: =INDEX(Data!AG:AG,MATCH($G113,Data!$A:$A,0),1) -> 1.1022134 | P113: =INDEX(Data!AH:AH,MATCH($G113,Data!$A:$A,0),1) -> 1.4555421 | Q113: =IFERROR(IF(MATCH(B113,#REF!,0)>0,1),0) -> 0
A114: Combustion of fuels | B114: Manufacture of ceramic sanitary fixtures | C114: Non-metallic mineral products | D114: Non-metallic minerals | E114: Ceramics | F114: 1 | G114: Ceramics [WA] | H114: =INDEX(Data!G:G,MATCH(G114,Data!A:A,0),1) -> 0.12876363 | I114: =INDEX(Data!J:J,MATCH(G114,Data!A:A,0),1) -> 0.095090361 | J114: =INDEX(Data!R:R,MATCH(G114,Data!A:A,0),1) -> 3.0746808 | K114: =INDEX(Data!S:S,MATCH(G114,Data!A:A,0),1) -> 0 | L114: =IF(B114="",A114,A114&"_"&B114) -> Combustion of fuels_Manufacture of ceramic sanitary fixtures | M114: =INDEX(Data!AD:AD,MATCH($G114,Data!$A:$A,0),1) -> 0.6 | N114: =INDEX(Data!AE:AE,MATCH($G114,Data!$A:$A,0),1) -> 0.598 | O114: =INDEX(Data!AG:AG,MATCH($G114,Data!$A:$A,0),1) -> 1.1022134 | P114: =INDEX(Data!AH:AH,MATCH($G114,Data!$A:$A,0),1) -> 1.4555421 | Q114: =IFERROR(IF(MATCH(B114,#REF!,0)>0,1),0) -> 0
A115: Combustion of fuels | B115: Manufacture of ceramic tiles and flags | C115: Non-metallic mineral products | D115: Non-metallic minerals | E115: Ceramics | F115: 2 | G115: Ceramics [WA] | H115: =INDEX(Data!G:G,MATCH(G115,Data!A:A,0),1) -> 0.12876363 | I115: =INDEX(Data!J:J,MATCH(G115,Data!A:A,0),1) -> 0.095090361 | J115: =INDEX(Data!R:R,MATCH(G115,Data!A:A,0),1) -> 3.0746808 | K115: =INDEX(Data!S:S,MATCH(G115,Data!A:A,0),1) -> 0 | L115: =IF(B115="",A115,A115&"_"&B115) -> Combustion of fuels_Manufacture of ceramic tiles and flags | M115: =INDEX(Data!AD:AD,MATCH($G115,Data!$A:$A,0),1) -> 0.6 | N115: =INDEX(Data!AE:AE,MATCH($G115,Data!$A:$A,0),1) -> 0.598 | O115: =INDEX(Data!AG:AG,MATCH($G115,Data!$A:$A,0),1) -> 1.1022134 | P115: =INDEX(Data!AH:AH,MATCH($G115,Data!$A:$A,0),1) -> 1.4555421 | Q115: =IFERROR(IF(MATCH(B115,#REF!,0)>0,1),0) -> 0
A116: Combustion of fuels | B116: Manufacture of basic pharmaceutical products | C116: Pharmaceuticals | D116: Chemicals | E116: Pharmaceuticals | F116: 23 | G116: Chemicals [WA] | H116: =INDEX(Data!G:G,MATCH(G116,Data!A:A,0),1) -> 1.1838611 | I116: =INDEX(Data!J:J,MATCH(G116,Data!A:A,0),1) -> 1.0013516 | J116: =INDEX(Data!R:R,MATCH(G116,Data!A:A,0),1) -> 2.6802341 | K116: =INDEX(Data!S:S,MATCH(G116,Data!A:A,0),1) -> 27.108503 | L116: =IF(B116="",A116,A116&"_"&B116) -> Combustion of fuels_Manufacture of basic pharmaceutical products | M116: =INDEX(Data!AD:AD,MATCH($G116,Data!$A:$A,0),1) -> 0.812 | N116: =INDEX(Data!AE:AE,MATCH($G116,Data!$A:$A,0),1) -> 0.739 | O116: =INDEX(Data!AG:AG,MATCH($G116,Data!$A:$A,0),1) -> 1.326565 | P116: =INDEX(Data!AH:AH,MATCH($G116,Data!$A:$A,0),1) -> 6.8406135 | Q116: =IFERROR(IF(MATCH(B116,#REF!,0)>0,1),0) -> 0
A117: Combustion of fuels | B117: Manufacture of dyes and pigments | C117: Chemicals | D117: Chemicals | E117: Chemicals | F117: 10 | G117: Chemicals [WA] | H117: =INDEX(Data!G:G,MATCH(G117,Data!A:A,0),1) -> 1.1838611 | I117: =INDEX(Data!J:J,MATCH(G117,Data!A:A,0),1) -> 1.0013516 | J117: =INDEX(Data!R:R,MATCH(G117,Data!A:A,0),1) -> 2.6802341 | K117: =INDEX(Data!S:S,MATCH(G117,Data!A:A,0),1) -> 27.108503 | L117: =IF(B117="",A117,A117&"_"&B117) -> Combustion of fuels_Manufacture of dyes and pigments | M117: =INDEX(Data!AD:AD,MATCH($G117,Data!$A:$A,0),1) -> 0.812 | N117: =INDEX(Data!AE:AE,MATCH($G117,Data!$A:$A,0),1) -> 0.739 | O117: =INDEX(Data!AG:AG,MATCH($G117,Data!$A:$A,0),1) -> 1.326565 | P117: =INDEX(Data!AH:AH,MATCH($G117,Data!$A:$A,0),1) -> 6.8406135 | Q117: =IFERROR(IF(MATCH(B117,#REF!,0)>0,1),0) -> 0
A118: Combustion of fuels | B118: Manufacture of explosives | C118: Chemicals | D118: Chemicals | E118: Chemicals | F118: 1 | G118: Chemicals [WA] | H118: =INDEX(Data!G:G,MATCH(G118,Data!A:A,0),1) -> 1.1838611 | I118: =INDEX(Data!J:J,MATCH(G118,Data!A:A,0),1) -> 1.0013516 | J118: =INDEX(Data!R:R,MATCH(G118,Data!A:A,0),1) -> 2.6802341 | K118: =INDEX(Data!S:S,MATCH(G118,Data!A:A,0),1) -> 27.108503 | L118: =IF(B118="",A118,A118&"_"&B118) -> Combustion of fuels_Manufacture of explosives | M118: =INDEX(Data!AD:AD,MATCH($G118,Data!$A:$A,0),1) -> 0.812 | N118: =INDEX(Data!AE:AE,MATCH($G118,Data!$A:$A,0),1) -> 0.739 | O118: =INDEX(Data!AG:AG,MATCH($G118,Data!$A:$A,0),1) -> 1.326565 | P118: =INDEX(Data!AH:AH,MATCH($G118,Data!$A:$A,0),1) -> 6.8406135 | Q118: =IFERROR(IF(MATCH(B118,#REF!,0)>0,1),0) -> 0
A119: Combustion of fuels | B119: Manufacture of fertilisers and nitrogen compounds | C119: Chemicals | D119: Chemicals | E119: Chemicals | F119: 29 | G119: Chemicals [Ammonia and Nitric Acid subset, WA] | H119: =INDEX(Data!G:G,MATCH(G119,Data!A:A,0),1) -> 1.7186343 | I119: =INDEX(Data!J:J,MATCH(G119,Data!A:A,0),1) -> 1.3535744 | J119: =INDEX(Data!R:R,MATCH(G119,Data!A:A,0),1) -> 0 | K119: =INDEX(Data!S:S,MATCH(G119,Data!A:A,0),1) -> 12.596122 | L119: =IF(B119="",A119,A119&"_"&B119) -> Combustion of fuels_Manufacture of fertilisers and nitrogen compounds | M119: =INDEX(Data!AD:AD,MATCH($G119,Data!$A:$A,0),1) -> 0.812 | N119: =INDEX(Data!AE:AE,MATCH($G119,Data!$A:$A,0),1) -> 0.739 | O119: =INDEX(Data!AG:AG,MATCH($G119,Data!$A:$A,0),1) -> 1.3999903 | P119: =INDEX(Data!AH:AH,MATCH($G119,Data!$A:$A,0),1) -> 3.5899569 | Q119: =IFERROR(IF(MATCH(B119,#REF!,0)>0,1),0) -> 0
... A277: Combustion of fuels | B277: Manufacture of rubber tyres and tubes | C277: Rubber & plastic | D277: Chemicals | E277: Chemicals | F277: 23 | G277: Chemicals [WA, Plastics subset] | H277: =INDEX(Data!G:G,MATCH(G277,Data!A:A,0),1) -> 0.49494039 | I277: =INDEX(Data!J:J,MATCH(G277,Data!A:A,0),1) -> 0.76276347 | J277: =INDEX(Data!R:R,MATCH(G277,Data!A:A,0),1) -> 6.0728236 | K277: =INDEX(Data!S:S,MATCH(G277,Data!A:A,0),1) -> 0 | L277: =IF(B277="",A277,A277&"_"&B277) -> Combustion of fuels_Manufacture of rubber tyres and tubes | M277: =INDEX(Data!AD:AD,MATCH($G277,Data!$A:$A,0),1) -> 0.812 | N277: =INDEX(Data!AE:AE,MATCH($G277,Data!$A:$A,0),1) -> 0.739 | O277: =INDEX(Data!AG:AG,MATCH($G277,Data!$A:$A,0),1) -> 1.2983192 | P277: =INDEX(Data!AH:AH,MATCH($G277,Data!$A:$A,0),1) -> 4.8395672 | Q277: =IFERROR(IF(MATCH(B277,#REF!,0)>0,1),0) -> 0
A278: Combustion of fuels | D278: Other | E278: Other combustion | G278: Fuel Benchmark | H278: =INDEX(Data!G:G,MATCH(G278,Data!A:A,0),1) -> 0.0579 | I278: =INDEX(Data!J:J,MATCH(G278,Data!A:A,0),1) -> 0.0426 | J278: =INDEX(Data!R:R,MATCH(G278,Data!A:A,0),1) -> 1 | K278: =INDEX(Data!S:S,MATCH(G278,Data!A:A,0),1) -> 0 | L278: =IF(B278="",A278,A278&"_"&B278) -> Combustion of fuels | M278: =INDEX(Data!AD:AD,MATCH($G278,Data!$A:$A,0),1) -> 0.782 | N278: =INDEX(Data!AE:AE,MATCH($G278,Data!$A:$A,0),1) -> 0.635 | O278: =INDEX(Data!AG:AG,MATCH($G278,Data!$A:$A,0),1) -> 1.1486857 | P278: =INDEX(Data!AH:AH,MATCH($G278,Data!$A:$A,0),1) -> 1.7068865 | Q278: =IFERROR(IF(MATCH(B278,#REF!,0)>0,1),0) -> 0
A279: Industrial plants for the production of (a) pulp from timber or other fibrous materials (b) paper and board | B279: Manufacture of paper and paperboard | C279: Pulp & Paper | D279: Pulp & paper | E279: Paper | F279: 70 | G279: Paper [WA] | H279: =INDEX(Data!G:G,MATCH(G279,Data!A:A,0),1) -> 0.22011858 | I279: =INDEX(Data!J:J,MATCH(G279,Data!A:A,0),1) -> 0.22144474 | J279: =INDEX(Data!R:R,MATCH(G279,Data!A:A,0),1) -> 6.1071929 | K279: =INDEX(Data!S:S,MATCH(G279,Data!A:A,0),1) -> 0 | L279: =IF(B279="",A279,A279&"_"&B279) -> Industrial plants for the production of (a) pulp from timber or other fibrous materials (b) paper and board_Manufacture of paper and paperboard | M279: =INDEX(Data!AD:AD,MATCH($G279,Data!$A:$A,0),1) -> 0.798 | N279: =INDEX(Data!AE:AE,MATCH($G279,Data!$A:$A,0),1) -> 0.921 | O279: =INDEX(Data!AG:AG,MATCH($G279,Data!$A:$A,0),1) -> 1.280909 | P279: =INDEX(Data!AH:AH,MATCH($G279,Data!$A:$A,0),1) -> 4.1862578 | Q279: =IFERROR(IF(MATCH(B279,#REF!,0)>0,1),0) -> 0
A280: Industrial plants for the production of (a) pulp from timber or other fibrous materials (b) paper and board | B280: Electric power generation, transmission and distribution | C280: Electricity, gas, steam and air conditioning supply | D280: Power and heat | E280: Power and heat | F280: 1 | G280: Fuel Benchmark | H280: =INDEX(Data!G:G,MATCH(G280,Data!A:A,0),1) -> 0.0579 | I280: =INDEX(Data!J:J,MATCH(G280,Data!A:A,0),1) -> 0.0426 | J280: =INDEX(Data!R:R,MATCH(G280,Data!A:A,0),1) -> 1 | K280: =INDEX(Data!S:S,MATCH(G280,Data!A:A,0),1) -> 0 | L280: =IF(B280="",A280,A280&"_"&B280) -> Industrial plants for the production of (a) pulp from timber or other fibrous materials (b) paper and board_Electric power generation, transmission and distribution | M280: =INDEX(Data!AD:AD,MATCH($G280,Data!$A:$A,0),1) -> 0.782 | N280: =INDEX(Data!AE:AE,MATCH($G280,Data!$A:$A,0),1) -> 0.635 | O280: =INDEX(Data!AG:AG,MATCH($G280,Data!$A:$A,0),1) -> 1.1486857 | P280: =INDEX(Data!AH:AH,MATCH($G280,Data!$A:$A,0),1) -> 1.7068865 | Q280: =IFERROR(IF(MATCH(B280,#REF!,0)>0,1),0) -> 0
A281: Industrial plants for the production of (a) pulp from timber or other fibrous materials (b) paper and board | B281: Electricity, gas, steam and air conditioning supply | C281: Electricity, gas, steam and air conditioning supply | D281: Power and heat | E281: Power and heat | F281: 1 | G281: Heat Benchmark | H281: =INDEX(Data!G:G,MATCH(G281,Data!A:A,0),1) -> 0.0768 | I281: =INDEX(Data!J:J,MATCH(G281,Data!A:A,0),1) -> 0.0473 | J281: =INDEX(Data!R:R,MATCH(G281,Data!A:A,0),1) -> 1 | K281: =INDEX(Data!S:S,MATCH(G281,Data!A:A,0),1) -> 0 | L281: =IF(B281="",A281,A281&"_"&B281) -> Industrial plants for the production of (a) pulp from timber or other fibrous materials (b) paper and board_Electricity, gas, steam and air conditioning supply | M281: =INDEX(Data!AD:AD,MATCH($G281,Data!$A:$A,0),1) -> 0.782 | N281: =INDEX(Data!AE:AE,MATCH($G281,Data!$A:$A,0),1) -> 0.635 | O281: =INDEX(Data!AG:AG,MATCH($G281,Data!$A:$A,0),1) -> 1.1486857 | P281: =INDEX(Data!AH:AH,MATCH($G281,Data!$A:$A,0),1) -> 1.7068865 | Q281: =IFERROR(IF(MATCH(B281,#REF!,0)>0,1),0) -> 0
A282: Industrial plants for the production of (a) pulp from timber or other fibrous materials (b) paper and board | B282: Manufacture of pulp | C282: Pulp & Paper | D282: Pulp & paper | E282: Pulp | F282: 9 | G282: Pulp [WA] | H282: =INDEX(Data!G:G,MATCH(G282,Data!A:A,0),1) -> 0.070004406 | I282: =INDEX(Data!J:J,MATCH(G282,Data!A:A,0),1) -> 0.046589293 | J282: =INDEX(Data!R:R,MATCH(G282,Data!A:A,0),1) -> 3.2582614 | K282: =INDEX(Data!S:S,MATCH(G282,Data!A:A,0),1) -> 0 | L282: =IF(B282="",A282,A282&"_"&B282) -> Industrial plants for the production of (a) pulp from timber or other fibrous materials (b) paper and board_Manufacture of pulp | M282: =INDEX(Data!AD:AD,MATCH($G282,Data!$A:$A,0),1) -> 0.798 | N282: =INDEX(Data!AE:AE,MATCH($G282,Data!$A:$A,0),1) -> 0.921 | O282: =INDEX(Data!AG:AG,MATCH($G282,Data!$A:$A,0),1) -> 1.280909 | P282: =INDEX(Data!AH:AH,MATCH($G282,Data!$A:$A,0),1) -> 4.1862578 | Q282: =IFERROR(IF(MATCH(B282,#REF!,0)>0,1),0) -> 0
A283: Industrial plants for the production of (a) pulp from timber or other fibrous materials (b) paper and board | B283: Manufacture of household and sanitary goods and of toilet requisites | C283: Pulp & Paper | D283: Pulp & paper | E283: Paper | F283: 1 | G283: Paper [WA] | H283: =INDEX(Data!G:G,MATCH(G283,Data!A:A,0),1) -> 0.22011858 | I283: =INDEX(Data!J:J,MATCH(G283,Data!A:A,0),1) -> 0.22144474 | J283: =INDEX(Data!R:R,MATCH(G283,Data!A:A,0),1) -> 6.1071929 | K283: =INDEX(Data!S:S,MATCH(G283,Data!A:A,0),1) -> 0 | L283: =IF(B283="",A283,A283&"_"&B283) -> Industrial plants for the production of (a) pulp from timber or other fibrous materials (b) paper and board_Manufacture of household and sanitary goods and of toilet requisites | M283: =INDEX(Data!AD:AD,MATCH($G283,Data!$A:$A,0),1) -> 0.798 | N283: =INDEX(Data!AE:AE,MATCH($G283,Data!$A:$A,0),1) -> 0.921 | O283: =INDEX(Data!AG:AG,MATCH($G283,Data!$A:$A,0),1) -> 1.280909 | P283: =INDEX(Data!AH:AH,MATCH($G283,Data!$A:$A,0),1) -> 4.1862578 | Q283: =IFERROR(IF(MATCH(B283,#REF!,0)>0,1),0) -> 0
A284: Industrial plants for the production of (a) pulp from timber or other fibrous materials (b) paper and board | D284: Pulp & paper | E284: 0 | G284: Pulp & Paper [WA] | H284: =INDEX(Data!G:G,MATCH(G284,Data!A:A,0),1) -> 0.19771476 | I284: =INDEX(Data!J:J,MATCH(G284,Data!A:A,0),1) -> 0.20319124 | J284: =INDEX(Data!R:R,MATCH(G284,Data!A:A,0),1) -> 4.9612622 | K284: =INDEX(Data!S:S,MATCH(G284,Data!A:A,0),1) -> 0 | L284: =IF(B284="",A284,A284&"_"&B284) -> Industrial plants for the production of (a) pulp from timber or other fibrous materials (b) paper and board | M284: =INDEX(Data!AD:AD,MATCH($G284,Data!$A:$A,0),1) -> 0.798 | N284: =INDEX(Data!AE:AE,MATCH($G284,Data!$A:$A,0),1) -> 0.921 | O284: =INDEX(Data!AG:AG,MATCH($G284,Data!$A:$A,0),1) -> 1.280909 | P284: =INDEX(Data!AH:AH,MATCH($G284,Data!$A:$A,0),1) -> 4.1862578 | Q284: =IFERROR(IF(MATCH(B284,#REF!,0)>0,1),0) -> 0
A285: Installations for the manufacture of ceramic products by firing, in particular roofing tiles, bricks, refractory bricks, tiles, stoneware or porcelain | B285: Manufacture of concrete products for construction purposes | C285: Non-metallic mineral products | D285: Non-metallic minerals | E285: Cement | F285: 1 | G285: Cement [WA] | H285: =INDEX(Data!G:G,MATCH(G285,Data!A:A,0),1) -> 0.81745071 | I285: =INDEX(Data!J:J,MATCH(G285,Data!A:A,0),1) -> 0.6991394 | J285: =INDEX(Data!R:R,MATCH(G285,Data!A:A,0),1) -> 4.32 | K285: =INDEX(Data!S:S,MATCH(G285,Data!A:A,0),1) -> 0 | L285: =IF(B285="",A285,A285&"_"&B285) -> Installations for the manufacture of ceramic products by firing, in particular roofing tiles, bricks, refractory bricks, tiles, stoneware or porcelain_Manufacture of concrete products for construction purposes | M285: =INDEX(Data!AD:AD,MATCH($G285,Data!$A:$A,0),1) -> 0.6 | N285: =INDEX(Data!AE:AE,MATCH($G285,Data!$A:$A,0),1) -> 0.598 | O285: =INDEX(Data!AG:AG,MATCH($G285,Data!$A:$A,0),1) -> 1.7474276 | P285: =INDEX(Data!AH:AH,MATCH($G285,Data!$A:$A,0),1) -> 11.543913 | Q285: =IFERROR(IF(MATCH(B285,#REF!,0)>0,1),0) -> 0
A286: Installations for the manufacture of ceramic products by firing, in particular roofing tiles, bricks, refractory bricks, tiles, stoneware or porcelain | B286: Manufacture of bricks, tiles and construction products, in baked clay | C286: Non-metallic mineral products | D286: Non-metallic minerals | E286: Ceramics | F286: 59 | G286: Ceramics [WA] | H286: =INDEX(Data!G:G,MATCH(G286,Data!A:A,0),1) -> 0.12876363 | I286: =INDEX(Data!J:J,MATCH(G286,Data!A:A,0),1) -> 0.095090361 | J286: =INDEX(Data!R:R,MATCH(G286,Data!A:A,0),1) -> 3.0746808 | K286: =INDEX(Data!S:S,MATCH(G286,Data!A:A,0),1) -> 0 | L286: =IF(B286="",A286,A286&"_"&B286) -> Installations for the manufacture of ceramic products by firing, in particular roofing tiles, bricks, refractory bricks, tiles, stoneware or porcelain_Manufacture of bricks, tiles and construction products, in baked clay | M286: =INDEX(Data!AD:AD,MATCH($G286,Data!$A:$A,0),1) -> 0.6 | N286: =INDEX(Data!AE:AE,MATCH($G286,Data!$A:$A,0),1) -> 0.598 | O286: =INDEX(Data!AG:AG,MATCH($G286,Data!$A:$A,0),1) -> 1.1022134 | P286: =INDEX(Data!AH:AH,MATCH($G286,Data!$A:$A,0),1) -> 1.4555421 | Q286: =IFERROR(IF(MATCH(B286,#REF!,0)>0,1),0) -> 0
A287: Installations for the manufacture of ceramic products by firing, in particular roofing tiles, bricks, refractory bricks, tiles, stoneware or porcelain | B287: Manufacture of ceramic household and ornamental articles | C287: Non-metallic mineral products | D287: Non-metallic minerals | E287: Ceramics | F287: 89 | G287: Ceramics [WA] | H287: =INDEX(Data!G:G,MATCH(G287,Data!A:A,0),1) -> 0.12876363 | I287: =INDEX(Data!J:J,MATCH(G287,Data!A:A,0),1) -> 0.095090361 | J287: =INDEX(Data!R:R,MATCH(G287,Data!A:A,0),1) -> 3.0746808 | K287: =INDEX(Data!S:S,MATCH(G287,Data!A:A,0),1) -> 0 | L287: =IF(B287="",A287,A287&"_"&B287) -> Installations for the manufacture of ceramic products by firing, in particular roofing tiles, bricks, refractory bricks, tiles, stoneware or porcelain_Manufacture of ceramic household and ornamental articles | M287: =INDEX(Data!AD:AD,MATCH($G287,Data!$A:$A,0),1) -> 0.6 | N287: =INDEX(Data!AE:AE,MATCH($G287,Data!$A:$A,0),1) -> 0.598 | O287: =INDEX(Data!AG:AG,MATCH($G287,Data!$A:$A,0),1) -> 1.1022134 | P287: =INDEX(Data!AH:AH,MATCH($G287,Data!$A:$A,0),1) -> 1.4555421 | Q287: =IFERROR(IF(MATCH(B287,#REF!,0)>0,1),0) -> 0
A288: Installations for the manufacture of ceramic products by firing, in particular roofing tiles, bricks, refractory bricks, tiles, stoneware or porcelain | B288: Manufacture of ceramic sanitary fixtures | C288: Non-metallic mineral products | D288: Non-metallic minerals | E288: Ceramics | F288: 3 | G288: Ceramics [WA] | H288: =INDEX(Data!G:G,MATCH(G288,Data!A:A,0),1) -> 0.12876363 | I288: =INDEX(Data!J:J,MATCH(G288,Data!A:A,0),1) -> 0.095090361 | J288: =INDEX(Data!R:R,MATCH(G288,Data!A:A,0),1) -> 3.0746808 | K288: =INDEX(Data!S:S,MATCH(G288,Data!A:A,0),1) -> 0 | L288: =IF(B288="",A288,A288&"_"&B288) -> Installations for the manufacture of ceramic products by firing, in particular roofing tiles, bricks, refractory bricks, tiles, stoneware or porcelain_Manufacture of ceramic sanitary fixtures | M288: =INDEX(Data!AD:AD,MATCH($G288,Data!$A:$A,0),1) -> 0.6 | N288: =INDEX(Data!AE:AE,MATCH($G288,Data!$A:$A,0),1) -> 0.598 | O288: =INDEX(Data!AG:AG,MATCH($G288,Data!$A:$A,0),1) -> 1.1022134 | P288: =INDEX(Data!AH:AH,MATCH($G288,Data!$A:$A,0),1) -> 1.4555421 | Q288: =IFERROR(IF(MATCH(B288,#REF!,0)>0,1),0) -> 0
A289: Installations for the manufacture of ceramic products by firing, in particular roofing tiles, bricks, refractory bricks, tiles, stoneware or porcelain | B289: Manufacture of ceramic tiles and flags | C289: Non-metallic mineral products | D289: Non-metallic minerals | E289: Ceramics | F289: 24 | G289: Ceramics [WA] | H289: =INDEX(Data!G:G,MATCH(G289,Data!A:A,0),1) -> 0.12876363 | I289: =INDEX(Data!J:J,MATCH(G289,Data!A:A,0),1) -> 0.095090361 | J289: =INDEX(Data!R:R,MATCH(G289,Data!A:A,0),1) -> 3.0746808 | K289: =INDEX(Data!S:S,MATCH(G289,Data!A:A,0),1) -> 0 | L289: =IF(B289="",A289,A289&"_"&B289) -> Installations for the manufacture of ceramic products by firing, in particular roofing tiles, bricks, refractory bricks, tiles, stoneware or porcelain_Manufacture of ceramic tiles and flags | M289: =INDEX(Data!AD:AD,MATCH($G289,Data!$A:$A,0),1) -> 0.6 | N289: =INDEX(Data!AE:AE,MATCH($G289,Data!$A:$A,0),1) -> 0.598 | O289: =INDEX(Data!AG:AG,MATCH($G289,Data!$A:$A,0),1) -> 1.1022134 | P289: =INDEX(Data!AH:AH,MATCH($G289,Data!$A:$A,0),1) -> 1.4555421 | Q289: =IFERROR(IF(MATCH(B289,#REF!,0)>0,1),0) -> 0
...

Sheet Sheet1
K31: =375+150+200+50 -> 775

Sheet Data
B1: Tags | G1: Emissions factors (tCO2e/t production) | M1: Status | N1: Process temperature | O1: Note | P1: Production | Q1: Source | R1: SEC (Fuel) | S1: SEC (Feedstock) | AC1: Note | AD1: Market growth EU SAM GEM3 22 | AF1: Note | AG1: Market growth (Alt)
B2: A | C2: B | D2: C | E2: D | G2: Weighted | J2: Allocation | M2: Status | N2: Peak process temperature | O2: Note | P2: T | R2: GJ/T | S2: GJ/T | T2: IEA Fuel | U2: IEA Feedstock | V2: Fraunhofer | W2: SEC Fuel (Neuwirth) | X2: SEC Feedstock (Neuwirth) | Z2: SEC Fuel (Kiemel) | AA2: SEC Feedstock (Kiemel) | AD2: %, 2023-2030 | AE2: %, 2030-2050 | AG2: %, 2023-2030 | AH2: %, 2030-2050
G3: T/CO2e | H3: T | J3: T/CO2e | K3: T | W3: GJ/T | X3: GJ/T
A4: Non-ferrous metals
A5: [Primary] Aluminium | G5: 1.641 | J5: 1.464 | M5: Confirmed | N5: >500 (primary), 200-500 (processing) | P5: =IFERROR(K5/J5,0) -> 0 | Q5: Kiemel et al (2024) | R5: =(1.28+0.4+0.3)*3.6+(0.69+0.67)*3.6 -> 12.024 | S5: 0 | V5: 25 | W5: 34 | AC5: Non-ferrous metals | AD5: 0.804 | AE5: 0.858 | AF5: Non-ferrous metals | AG5: 1.3517721 | AH5: 3.1982578
A6: Copper [n.a.] | G6: 1.4 | J6: 1.4 | M6: Confirmed | N6: >500 (primary), 200-500 (processing) | P6: =IFERROR(K6/J6,0) -> 0 | Q6: Kiemel et al (2024) | R6: =1.67*3.6+0.56*3.6 -> 8.028 | S6: 0 | W6: 11.6 | AC6: Non-ferrous metals | AD6: 0.804 | AE6: 0.858 | AF6: Non-ferrous metals | AG6: 1 | AH6: 1
A7: Lead, zinc and tin [n.a.] | G7: 1.92 | J7: 1.92 | M7: Confirmed | N7: >500 (primary), 200-500 (processing) | O7: Approx. Zinc and general metal processing | P7: =IFERROR(K7/J7,0) -> 0 | Q7: Kiemel et al (2024) | R7: =(0.14+0.14)*3.6+0.35*3.6 -> 2.268 | S7: 0 | W7: 11.6 | AC7: Non-ferrous metals | AD7: 0.804 | AE7: 0.858 | AF7: Non-ferrous metals | AG7: 1 | AH7: 1
A8: Non-ferrous metals [WA] | G8: =AVERAGE(G5:G7) -> 1.6536667 | J8: =AVERAGE(J5:J7) -> 1.5946667 | M8: Confirmed | N8: >500 (primary), 200-500 (processing) | O8: Approx. Zinc and general metal processing | P8: =IFERROR(K8/J8,0) -> 0 | Q8: Kiemel et al (2024) | R8: =(0.14+0.14)*3.6+0.35*3.6 -> 2.268 | S8: 0 | W8: 11.6 | AC8: Non-ferrous metals | AD8: 0.804 | AE8: 0.858 | AF8: Non-ferrous metals | AG8: 1 | AH8: 1
A9: Chemicals
A10: Ammonia | B10: Chemicals | C10: Inorganic | D10: Fertilizer | G10: 1.947 | H10: 30588525 | J10: 1.57 | K10: 23958607 | M10: Confirmed | N10: - | O10: Haber-Bosch process | P10: =IFERROR(K10/J10,0) -> 15260259 | Q10: Kiemel et al (2024) | R10: 0 | S10: =5.92*3.6 -> 21.312 | T10: =10.9-4.3 -> 6.6 | U10: 20.7 | X10: 21.312 | AA10: =5.92*3.6 -> 21.312 | AC10: Chemical products | AD10: 0.812 | AE10: 0.739 | AF10: Chemical products | AG10: 1.5336733 | AH10: 1.9468976
A11: Nitric acid | B11: Chemicals | C11: Inorganic | D11: Fertilizer | E11: Pharmaceuticals | G11: 0.205 | H11: 4614965 | J11: 0.23 | K11: 4614965 | M11: Confirmed | N11: - | O11: Ammonia oxidation (0.285t ammonia per to nitric acid) | P11: =IFERROR(K11/J11,0) -> 20065065 | Q11: Kiemel et al (2024) | R11: 0 | S11: =5.92*3.6*280/1000 -> 5.96736 | W11: 1.9040625 | Z11: =AVERAGE(0.12,0.51,0.27)*3.6 -> 1.08 | AA11: =3.14 -> 3.14 | AC11: Chemical products | AD11: 0.812 | AE11: 0.739 | AF11: Chemical products | AG11: 1.2983192 | AH11: 4.8395672
A12: Soda ash | B12: Chemicals | C12: Inorganic | G12: 0.945 | H12: 7218816 | J12: 0.753 | K12: 5497992 | M12: Confirmed | N12: 100-200 | O12: Solvay process / H2-burner in furnace | P12: =IFERROR(K12/J12,0) -> 7301450.2 | Q12: Kiemel et al (2024) | R12: =(0.94+0.94+1.26)*3.6 -> 11.304 | S12: 0 | U12: 11.1 | W12: 1.9040625 | Z12: =AVERAGE(0.94,1.26,0.94)*3.6 -> 3.768 | AC12: Chemical products | AD12: 0.812 | AE12: 0.739 | AF12: Chemical products | AG12: 1.1486857 | AH12: 1.2946752
A13: Carbon Black | B13: Chemicals | C13: Inorganic | G13: 1.824 | H13: 1824820 | J13: 1.485 | K13: 1394408 | M13: Confirmed | N13: > 500 | O13: H2 burner in furnace | P13: =IFERROR(K13/J13,0) -> 938995.29 | Q13: Kiemel et al (2024) | R13: =18*3.6 -> 64.8 | S13: 0 | T13: 32.8 | W13: 1.9040625 | Z13: =18*3.6 -> 64.8 | AC13: Chemical products | AD13: 0.812 | AE13: 0.739 | AF13: Chemical products | AG13: 1.2983192 | AH13: 4.8395672
A14: Steam cracking | B14: Chemicals | C14: Organic | G14: 0.849 | H14: 31393609 | J14: 0.681 | K14: 22816634 | M14: Confirmed | N14: - | O14: Methanol-to-Olefins (Etyhlene) | P14: =IFERROR(K14/J14,0) -> 33504602 | Q14: Kiemel et al (2024) | R14: 0 | S14: =17.67*3.6 -> 63.612 | T14: 11.5 | U14: =AVERAGE(0,0,45) -> 15 | X14: =(6.31+17.67)*3.6 -> 86.328 | AA14: =17.67*3.6 -> 63.612 | AC14: Chemical products | AD14: 0.812 | AE14: 0.739 | AF14: Chemical products | AG14: 1.3071001 | AH14: 12.835745
A15: Adipic Acid | B15: Chemicals | C15: Organic | D15: Plastics | E15: Pharmaceuticals | G15: 1.14 | H15: 857225 | J15: 2.12 | K15: 1468379 | M15: Confirmed | N15: <100 | O15: Primarily Steam, 20% efficiency upside | P15: =IFERROR(K15/J15,0) -> 692631.6 | Q15: IEA | R15: =T15 -> 21.6 | S15: =U15 -> 0 | T15: =21.6 -> 21.6 | W15: 1.9040625 | Z15: =AVERAGE(0.12,0.51,0.27)*3.6 -> 1.08 | AA15: =3.14 -> 3.14 | AC15: Chemical products | AD15: 0.812 | AE15: 0.739 | AF15: Chemical products | AG15: 1.2983192 | AH15: 4.8395672
A16: Aromatics | B16: Chemicals | C16: Organic | G16: =0.0072*1/0.056 -> 0.12857143 | H16: 1896871 | J16: =0.0228*1/0.056 -> 0.40714286 | K16: 1139604 | M16: Confirmed | N16: > 500 | O16: Average of Benzene, Toluene, Xylone aromatics extraction, 20% efficiency upside | P16: =IFERROR(K16/J16,0) -> 2799027.4 | Q16: IEA | R16: =T16 -> 2.2 | S16: =U16 -> 37.333333 | T16: 2.2 | U16: =AVERAGE(45,22,45) -> 37.333333 | W16: 1.9040625 | Z16: =AVERAGE(0.12,0.51,0.27)*3.6 -> 1.08 | AA16: =3.14 -> 3.14 | AC16: Chemical products | AD16: 0.812 | AE16: 0.739 | AF16: Chemical products | AG16: 1.2983192 | AH16: 4.8395672
A17: Styrene | B17: Chemicals | C17: Organic | D17: Plastics | G17: 0.558 | H17: 2676322 | J17: 0.401 | K17: 1655811 | M17: Confirmed | N17: > 500 | O17: Steam, 20% efficiency upside | P17: =IFERROR(K17/J17,0) -> 4129204.5 | Q17: IEA | R17: =T17 -> 8.6 | S17: =U17 -> 0 | T17: 8.6 | X17: =(6.31+17.67)*3.6 -> 86.328 | Z17: =AVERAGE(0.12,0.51,0.27)*3.6 -> 1.08 | AA17: =3.14 -> 3.14 | AC17: Chemical products | AD17: 0.812 | AE17: 0.739 | AF17: Chemical products | AG17: 1.2983192 | AH17: 4.8395672
A18: Phenol/Acetone | B18: Chemicals | C18: Organic | D18: Plastics | G18: 0.319 | H18: 1200943 | J18: 0.23 | K18: 812138 | M18: Confirmed | N18: 100-200 | O18: Steam, 20% efficiency upside | P18: =IFERROR(K18/J18,0) -> 3531034.8 | Q18: IEA | R18: =T18 -> 10.5 | S18: =U18 -> 0 | T18: =AVERAGE(10.1,10.9) -> 10.5 | X18: =(6.31+17.67)*3.6 -> 86.328 | Z18: =AVERAGE(0.12,0.51,0.27)*3.6 -> 1.08 | AA18: =3.14 -> 3.14 | AC18: Chemical products | AD18: 0.812 | AE18: 0.739 | AF18: Chemical products | AG18: 1.2983192 | AH18: 4.8395672
A19: Ethylene oxide/ethylene glycol | B19: Chemicals | C19: Organic | D19: Plastics | E19: Pharmaceuticals | G19: 0.51 | H19: 1484310 | J19: 0.389 | K19: 839637 | M19: Confirmed | N19: 200-500 | O19: Steam, 20% efficiency upside | P19: =IFERROR(K19/J19,0) -> 2158449.9 | Q19: IEA | R19: =T19 -> 3.65 | S19: =U19 -> 0 | T19: =AVERAGE(2.5,4.8) -> 3.65 | W19: 1.9040625 | Z19: =AVERAGE(0.12,0.51,0.27)*3.6 -> 1.08 | AA19: =3.14 -> 3.14 | AC19: Chemical products | AD19: 0.812 | AE19: 0.739 | AF19: Chemical products | AG19: 1.2983192 | AH19: 4.8395672
A20: Vinyl chloride monomer | B20: Chemicals | C20: Organic | D20: Plastics | G20: 0.277 | H20: 1639059 | J20: 0.155 | K20: 758335 | M20: Confirmed | N20: > 500 | O20: Primarily Fuel, 20% efficiency upside | P20: =IFERROR(K20/J20,0) -> 4892483.9 | Q20: IEA | R20: =T20 -> 2.7 | S20: =U20 -> 0 | T20: 2.7 | W20: 1.9040625 | Z20: =AVERAGE(0.12,0.51,0.27)*3.6 -> 1.08 | AA20: =3.14 -> 3.14 | AC20: Chemical products | AD20: 0.812 | AE20: 0.739 | AF20: Chemical products | AG20: 1.2983192 | AH20: 4.8395672
A21: S-PVC | B21: Chemicals | C21: Organic | D21: Plastics | G21: 0.12 | H21: 400288 | J21: 0.066 | K21: 216193 | M21: Confirmed | N21: <100 | O21: Steam, 20% efficiency upside | P21: =IFERROR(K21/J21,0) -> 3275651.5 | Q21: IEA | R21: =T21 -> 1.9 | S21: =U21 -> 0 | T21: 1.9 | W21: 1.9040625 | Z21: =AVERAGE(0.12,0.51,0.27)*3.6 -> 1.08 | AA21: =3.14 -> 3.14 | AC21: Chemical products | AD21: 0.812 | AE21: 0.739 | AF21: Chemical products | AG21: 1.2983192 | AH21: 4.8395672
A22: E-PVC | B22: Chemicals | C22: Organic | D22: Plastics | G22: 0.23 | H22: 96197 | J22: 0.181 | K22: 61707 | M22: Confirmed | N22: <100 | O22: Steam, 20% efficiency upside | P22: =IFERROR(K22/J22,0) -> 340922.65 | Q22: IEA | R22: =T22 -> 1.9 | S22: =U22 -> 0 | T22: 1.9 | W22: 1.9040625 | Z22: =AVERAGE(0.12,0.51,0.27)*3.6 -> 1.08 | AA22: =3.14 -> 3.14 | AC22: Chemical products | AD22: 0.812 | AE22: 0.739 | AF22: Chemical products | AG22: 1.2983192 | AH22: 4.8395672
A23: Hydrogen and SynGas
A24: Hydrogen | B24: Hydrogen and Syngas | G24: 8.88 | H24: 7051720 | J24: 6.84 | K24: 5074480 | M24: Confirmed | N24: - | O24: Hydrogen LHV | P24: =IFERROR(K24/J24,0) -> 741883.04 | Q24: NREL | S24: =1/8.33*1000 -> 120.04802 | X24: 3.6 | AA24: 3.6 | AC24: Chemical products | AD24: 0.812 | AE24: 0.739 | AF24: Chemical products | AG24: 1.2983192 | AH24: 4.8395672
A25: Snythetic Gas | B25: Hydrogen and Syngas | G25: 0.155 | H25: 357368 | J25: 0.187 | K25: 317371 | M25: Confirmed | N25: - | O25: Hydrogen LHV | P25: =IFERROR(K25/J25,0) -> 1697171.1 | Q25: NREL | S25: =1/8.33*1000 -> 120.04802 | X25: 3.6 | AA25: 3.6 | AC25: Chemical products | AD25: 0.812 | AE25: 0.739 | AF25: Chemical products | AG25: 1.2983192 | AH25: 4.8395672
A26: Iron & Steel
A27: Sintered ore | G27: 0.248 | H27: 23154801 | J27: 0.157 | K27: 14393515 | M27: Confirmed | N27: > 500 | O27: Updraft sintering | P27: =IFERROR(K27/J27,0) -> 91678439 | Q27: Kiemel et al (2024) | R27: =(0.12+0.5)*3.6 -> 2.232 | S27: 0 | V27: 0.3 | W27: 4.13424 | X27: 6.47352 | Z27: =3.33 -> 3.33 | AC27: Ferrous metals | AD27: 0.481 | AE27: 0.412 | AF27: Ferrous metals | AG27: 1.2895889 | AH27: 0.59422748
A28: Hot metal | B28: Integrated Steel | G28: 1.495 | H28: 128889587 | J28: 1.288 | K28: 110024564 | M28: Confirmed | N28: > 500 | O28: H2-DRI to hot metal | P28: =IFERROR(K28/J28,0) -> 85422798 | Q28: Kiemel et al (2024) | R28: =(0.83+3.33)*3.6 -> 14.976 | S28: =1.89*3.6 -> 6.804 | V28: =MEDIAN(5.3,6.8) -> 6.05 | W28: 4.13424 | X28: 6.47352 | AC28: Ferrous metals | AD28: 0.481 | AE28: 0.412 | AF28: Ferrous metals | AG28: 1.2895889 | AH28: 0.59422748
A29: EAF carbon steel | B29: Steel Processing | G29: 0.255 | H29: 9804572 | J29: 0.215 | K29: 2050637 | M29: Confirmed | N29: > 500 | O29: Ferrous metal processing, assuming no mass losses between liquid steel and rolling | P29: =IFERROR(K29/J29,0) -> 9537846.5 | Q29: Kiemel et al (2024) | R29: =(0.66+0.028)*3.6 -> 2.4768 | S29: 0 | V29: 2.2 | W29: 4.13424 | X29: 6.47352 | AC29: Ferrous metals | AD29: 0.481 | AE29: 0.412 | AF29: Ferrous metals | AG29: 1.2895889 | AH29: 0.59422748
A30: EAF high alloy steel | B30: Steel Processing | G30: 0.323 | H30: 8681596 | J30: 0.268 | K30: 2185759 | M30: Confirmed | N30: > 500 | O30: Ferrous metal processing, assuming no mass losses between liquid steel and rolling | P30: =IFERROR(K30/J30,0) -> 8155817.2 | Q30: Kiemel et al (2024) | R30: =(0.66+0.028)*3.6 -> 2.4768 | S30: 0 | V30: 2.2 | W30: 4.13424 | X30: 6.47352 | AC30: Ferrous metals | AD30: 0.481 | AE30: 0.412 | AF30: Ferrous metals | AG30: 1.2895889 | AH30: 0.59422748
A31: Iron casting | G31: 0.37 | H31: 1380242 | J31: 0.282 | K31: 930583 | M31: Confirmed | N31: > 500 | O31: Ferrous metal processing, assuming no mass losses between liquid steel and rolling | P31: =IFERROR(K31/J31,0) -> 3299939.7 | Q31: Kiemel et al (2024) | R31: =(0.66+0.028)*3.6 -> 2.4768 | S31: 0 | V31: 0.3 | W31: 4.13424 | X31: 6.47352 | AC31: Ferrous metals | AD31: 0.481 | AE31: 0.412 | AF31: Ferrous metals | AG31: 1.0573621 | AH31: 0.79755754
A32: Refining
A33: Refinery products | G33: =0.0308/0.056 -> 0.55 | J33: =0.0228/0.056 -> 0.40714286 | M33: Confirmed | N33: - | O33: No distinction applied between hydrocracking and hydrotreating | P33: =IFERROR(K33/J33,0) -> 0 | Q33: Kiemel et al (2024) | R33: 0 | S33: =0.12*3.6 -> 0.432 | X33: =(MEDIAN(0.389,0.639))*3.6 -> 1.8504 | AC33: Crude oil | AD33: 0.726 | AE33: 0.305 | AF33: Crude oil | AG33: 0.6341283 | AH33: 0.082400936
A34: Coke | G34: 0.282 | J34: 0.217 | M34: Confirmed | N34: - | O34: Excluded from consideration | P34: =IFERROR(K34/J34,0) -> 0 | Q34: Excluded | R34: 0 | S34: 0 | X34: 1.8504 | AC34: Crude oil | AD34: 0.726 | AE34: 0.305 | AF34: Crude oil | AG34: 0.6341283 | AH34: 0.082400936
A35: Non-metallic mineral products
A36: Grey cement clinker | B36: Non-metallic minerals | C36: Cement | G36: 0.81 | H36: 105321006 | J36: 0.693 | K36: 90105535 | M36: Confirmed | N36: >500 (Firing),100-300 (Drying) | O36: Approx. cement/clinker general | P36: =IFERROR(K36/J36,0) -> 1.3002242e+08 | Q36: Kiemel et al (2024) | R36: =(0.12+1.08)*3.6 -> 4.32 | S36: 0 | V36: 4 | W36: 3.492 | AC36: Non-metallic minerals | AD36: 0.6 | AE36: 0.598 | AF36: Non-metallic minerals | AG36: 1.7474276 | AH36: 11.543913
A37: White cement clinker | B37: Non-metallic minerals | C37: Cement | G37: 1.114 | H37: 2646157 | J37: 0.957 | K37: 2145323 | M37: Confirmed | N37: >500 (Firing),100-300 (Drying) | O37: Approx. cement/clinker general | P37: =IFERROR(K37/J37,0) -> 2241716.8 | Q37: Kiemel et al (2024) | R37: =(0.12+1.08)*3.6 -> 4.32 | S37: 0 | V37: 4 | W37: 3.492 | AC37: Non-metallic minerals | AD37: 0.6 | AE37: 0.598 | AF37: Non-metallic minerals | AG37: 1.7474276 | AH37: 11.543913
A38: Lime | B38: Non-metallic minerals | C38: Lime | G38: 1.059 | H38: 21751588 | J38: 0.725 | K38: 15062292 | M38: Confirmed | N38: > 500 | O38: Default to Neuwirth: Lime burning | P38: =IFERROR(K38/J38,0) -> 20775575 | Q38: Neuwirth et al (2022) | R38: =1.03*3.6 -> 3.708 | S38: 0 | W38: 3.708 | AC38: Non-metallic minerals | AD38: 0.6 | AE38: 0.598 | AF38: Non-metallic minerals | AG38: 1.9487171 | AH38: 118.49939
A39: Dolime | B39: Non-metallic minerals | C39: Lime | G39: 1.214 | H39: 1794640 | J39: 0.815 | K39: 1265828 | M39: Confirmed | N39: > 500 | O39: Default to Neuwirth: Lime burning | P39: =IFERROR(K39/J39,0) -> 1553163.2 | Q39: Neuwirth et al (2022) | R39: =1.03*3.6 -> 3.708 | S39: 0 | W39: 3.708 | AC39: Non-metallic minerals | AD39: 0.6 | AE39: 0.598 | AF39: Non-metallic minerals | AG39: 1.9487171 | AH39: 118.49939
A40: Sintered Dolime | B40: Non-metallic minerals | C40: Lime | G40: 1.535 | H40: 790184 | J40: 1.406 | K40: 722297 | M40: Confirmed | N40: > 500 | O40: Default to Neuwirth: Lime burning | P40: =IFERROR(K40/J40,0) -> 513724.75 | Q40: Neuwirth et al (2022) | R40: =1.03*3.6 -> 3.708 | S40: 0 | W40: 3.708 | AC40: Non-metallic minerals | AD40: 0.6 | AE40: 0.598 | AF40: Non-metallic minerals | AG40: 1.9487171 | AH40: 118.49939
...
